Workbook

Sheet Giving Pyramid
B2: Giving Pyramid — Individual Gifts
B4: Fiscal Year (Jul–Jun): | C4: 2025
B5: Period: | C5: =DATE(C4-1,7,1) -> 45474 | D5: ="to "&TEXT(DATE(C4,6,30),"mmm d, yyyy") -> to Jun 30, 2025
B7: Gift Range | C7: Low | D7: High | E7: # of Gifts | F7: Total $ | G7: Avg Gift | H7: % of Gifts | I7: % of Total $
B8: $25,000 + | C8: 25000 | D8: 100000000 | E8: =COUNTIFS('AHCF_Gifts_19952026 (1)'!$D:$D,">="&$C$5,'AHCF_Gifts_19952026 (1)'!$D:$D,"<="&DATE($C$4,6,30),'AHCF_Gifts_19952026 (1)'!$E:$E,">="&$C8,'AHCF_Gifts_19952026 (1)'!$E:$E,"<="&$D8) -> 9 | F8: =SUMIFS('AHCF_Gifts_19952026 (1)'!$E:$E,'AHCF_Gifts_19952026 (1)'!$D:$D,">="&$C$5,'AHCF_Gifts_19952026 (1)'!$D:$D,"<="&DATE($C$4,6,30),'AHCF_Gifts_19952026 (1)'!$E:$E,">="&$C8,'AHCF_Gifts_19952026 (1)'!$E:$E,"<="&$D8) -> 362090 | G8: =IF(E8=0,0,F8/E8) -> 40232.222 | H8: =IF($E$17=0,0,E8/$E$17) -> 0.0038643195 | I8: =IF($F$17=0,0,F8/$F$17) -> 0.23219441
B9: $10,000 – $24,999 | C9: 10000 | D9: 24999.99 | E9: =COUNTIFS('AHCF_Gifts_19952026 (1)'!$D:$D,">="&$C$5,'AHCF_Gifts_19952026 (1)'!$D:$D,"<="&DATE($C$4,6,30),'AHCF_Gifts_19952026 (1)'!$E:$E,">="&$C9,'AHCF_Gifts_19952026 (1)'!$E:$E,"<="&$D9) -> 33 | F9: =SUMIFS('AHCF_Gifts_19952026 (1)'!$E:$E,'AHCF_Gifts_19952026 (1)'!$D:$D,">="&$C$5,'AHCF_Gifts_19952026 (1)'!$D:$D,"<="&DATE($C$4,6,30),'AHCF_Gifts_19952026 (1)'!$E:$E,">="&$C9,'AHCF_Gifts_19952026 (1)'!$E:$E,"<="&$D9) -> 513208.59 | G9: =IF(E9=0,0,F9/E9) -> 15551.775 | H9: =IF($E$17=0,0,E9/$E$17) -> 0.014169171 | I9: =IF($F$17=0,0,F9/$F$17) -> 0.32910096
B10: $5,000 – $9,999 | C10: 5000 | D10: 9999.99 | E10: =COUNTIFS('AHCF_Gifts_19952026 (1)'!$D:$D,">="&$C$5,'AHCF_Gifts_19952026 (1)'!$D:$D,"<="&DATE($C$4,6,30),'AHCF_Gifts_19952026 (1)'!$E:$E,">="&$C10,'AHCF_Gifts_19952026 (1)'!$E:$E,"<="&$D10) -> 39 | F10: =SUMIFS('AHCF_Gifts_19952026 (1)'!$E:$E,'AHCF_Gifts_19952026 (1)'!$D:$D,">="&$C$5,'AHCF_Gifts_19952026 (1)'!$D:$D,"<="&DATE($C$4,6,30),'AHCF_Gifts_19952026 (1)'!$E:$E,">="&$C10,'AHCF_Gifts_19952026 (1)'!$E:$E,"<="&$D10) -> 213695.98 | G10: =IF(E10=0,0,F10/E10) -> 5479.3841 | H10: =IF($E$17=0,0,E10/$E$17) -> 0.016745384 | I10: =IF($F$17=0,0,F10/$F$17) -> 0.13703503
B11: $2,500 – $4,999 | C11: 2500 | D11: 4999.99 | E11: =COUNTIFS('AHCF_Gifts_19952026 (1)'!$D:$D,">="&$C$5,'AHCF_Gifts_19952026 (1)'!$D:$D,"<="&DATE($C$4,6,30),'AHCF_Gifts_19952026 (1)'!$E:$E,">="&$C11,'AHCF_Gifts_19952026 (1)'!$E:$E,"<="&$D11) -> 34 | F11: =SUMIFS('AHCF_Gifts_19952026 (1)'!$E:$E,'AHCF_Gifts_19952026 (1)'!$D:$D,">="&$C$5,'AHCF_Gifts_19952026 (1)'!$D:$D,"<="&DATE($C$4,6,30),'AHCF_Gifts_19952026 (1)'!$E:$E,">="&$C11,'AHCF_Gifts_19952026 (1)'!$E:$E,"<="&$D11) -> 99000 | G11: =IF(E11=0,0,F11/E11) -> 2911.7647 | H11: =IF($E$17=0,0,E11/$E$17) -> 0.01459854 | I11: =IF($F$17=0,0,F11/$F$17) -> 0.063484898
B12: $1,000 – $2,499 | C12: 1000 | D12: 2499.99 | E12: =COUNTIFS('AHCF_Gifts_19952026 (1)'!$D:$D,">="&$C$5,'AHCF_Gifts_19952026 (1)'!$D:$D,"<="&DATE($C$4,6,30),'AHCF_Gifts_19952026 (1)'!$E:$E,">="&$C12,'AHCF_Gifts_19952026 (1)'!$E:$E,"<="&$D12) -> 142 | F12: =SUMIFS('AHCF_Gifts_19952026 (1)'!$E:$E,'AHCF_Gifts_19952026 (1)'!$D:$D,">="&$C$5,'AHCF_Gifts_19952026 (1)'!$D:$D,"<="&DATE($C$4,6,30),'AHCF_Gifts_19952026 (1)'!$E:$E,">="&$C12,'AHCF_Gifts_19952026 (1)'!$E:$E,"<="&$D12) -> 185454.69 | G12: =IF(E12=0,0,F12/E12) -> 1306.0189 | H12: =IF($E$17=0,0,E12/$E$17) -> 0.060970374 | I12: =IF($F$17=0,0,F12/$F$17) -> 0.11892497
B13: $500 – $999 | C13: 500 | D13: 999.99 | E13: =COUNTIFS('AHCF_Gifts_19952026 (1)'!$D:$D,">="&$C$5,'AHCF_Gifts_19952026 (1)'!$D:$D,"<="&DATE($C$4,6,30),'AHCF_Gifts_19952026 (1)'!$E:$E,">="&$C13,'AHCF_Gifts_19952026 (1)'!$E:$E,"<="&$D13) -> 106 | F13: =SUMIFS('AHCF_Gifts_19952026 (1)'!$E:$E,'AHCF_Gifts_19952026 (1)'!$D:$D,">="&$C$5,'AHCF_Gifts_19952026 (1)'!$D:$D,"<="&DATE($C$4,6,30),'AHCF_Gifts_19952026 (1)'!$E:$E,">="&$C13,'AHCF_Gifts_19952026 (1)'!$E:$E,"<="&$D13) -> 60706.54 | G13: =IF(E13=0,0,F13/E13) -> 572.70321 | H13: =IF($E$17=0,0,E13/$E$17) -> 0.045513096 | I13: =IF($F$17=0,0,F13/$F$17) -> 0.038928773
B14: $250 – $499 | C14: 250 | D14: 499.99 | E14: =COUNTIFS('AHCF_Gifts_19952026 (1)'!$D:$D,">="&$C$5,'AHCF_Gifts_19952026 (1)'!$D:$D,"<="&DATE($C$4,6,30),'AHCF_Gifts_19952026 (1)'!$E:$E,">="&$C14,'AHCF_Gifts_19952026 (1)'!$E:$E,"<="&$D14) -> 95 | F14: =SUMIFS('AHCF_Gifts_19952026 (1)'!$E:$E,'AHCF_Gifts_19952026 (1)'!$D:$D,">="&$C$5,'AHCF_Gifts_19952026 (1)'!$D:$D,"<="&DATE($C$4,6,30),'AHCF_Gifts_19952026 (1)'!$E:$E,">="&$C14,'AHCF_Gifts_19952026 (1)'!$E:$E,"<="&$D14) -> 30724.38 | G14: =IF(E14=0,0,F14/E14) -> 323.41453 | H14: =IF($E$17=0,0,E14/$E$17) -> 0.040790039 | I14: =IF($F$17=0,0,F14/$F$17) -> 0.019702365
B15: $100 – $249 | C15: 100 | D15: 249.99 | E15: =COUNTIFS('AHCF_Gifts_19952026 (1)'!$D:$D,">="&$C$5,'AHCF_Gifts_19952026 (1)'!$D:$D,"<="&DATE($C$4,6,30),'AHCF_Gifts_19952026 (1)'!$E:$E,">="&$C15,'AHCF_Gifts_19952026 (1)'!$E:$E,"<="&$D15) -> 331 | F15: =SUMIFS('AHCF_Gifts_19952026 (1)'!$E:$E,'AHCF_Gifts_19952026 (1)'!$D:$D,">="&$C$5,'AHCF_Gifts_19952026 (1)'!$D:$D,"<="&DATE($C$4,6,30),'AHCF_Gifts_19952026 (1)'!$E:$E,">="&$C15,'AHCF_Gifts_19952026 (1)'!$E:$E,"<="&$D15) -> 40733.32 | G15: =IF(E15=0,0,F15/E15) -> 123.06139 | H15: =IF($E$17=0,0,E15/$E$17) -> 0.14212108 | I15: =IF($F$17=0,0,F15/$F$17) -> 0.026120714
B16: Under $100 | C16: 0.01 | D16: 99.99 | E16: =COUNTIFS('AHCF_Gifts_19952026 (1)'!$D:$D,">="&$C$5,'AHCF_Gifts_19952026 (1)'!$D:$D,"<="&DATE($C$4,6,30),'AHCF_Gifts_19952026 (1)'!$E:$E,">="&$C16,'AHCF_Gifts_19952026 (1)'!$E:$E,"<="&$D16) -> 1540 | F16: =SUMIFS('AHCF_Gifts_19952026 (1)'!$E:$E,'AHCF_Gifts_19952026 (1)'!$D:$D,">="&$C$5,'AHCF_Gifts_19952026 (1)'!$D:$D,"<="&DATE($C$4,6,30),'AHCF_Gifts_19952026 (1)'!$E:$E,">="&$C16,'AHCF_Gifts_19952026 (1)'!$E:$E,"<="&$D16) -> 53812.48 | G16: =IF(E16=0,0,F16/E16) -> 34.943169 | H16: =IF($E$17=0,0,E16/$E$17) -> 0.66122799 | I16: =IF($F$17=0,0,F16/$F$17) -> 0.034507877
B17: Total | E17: =SUM(E8:E16) -> 2329 | F17: =SUM(F8:F16) -> 1559426 | G17: =IF(E17=0,0,F17/E17) -> 669.56891 | H17: =SUM(H8:H16) -> 1 | I17: =SUM(I8:I16) -> 1
B19: Chart source (updates with FY)
B20: Year-over-Year Performance (all fiscal years)
B21: Fiscal Year | C21: Total $ | D21: # of Gifts
B22: 2011 | C22: =SUMIFS('AHCF_Gifts_19952026 (1)'!$E:$E,'AHCF_Gifts_19952026 (1)'!$D:$D,">="&DATE($B22-1,7,1),'AHCF_Gifts_19952026 (1)'!$D:$D,"<="&DATE($B22,6,30)) -> 856703.38 | D22: =COUNTIFS('AHCF_Gifts_19952026 (1)'!$D:$D,">="&DATE($B22-1,7,1),'AHCF_Gifts_19952026 (1)'!$D:$D,"<="&DATE($B22,6,30)) -> 1688 | N22: ="FY"&B22 -> FY2011
B23: =B22+1 -> 2012 | C23: =SUMIFS('AHCF_Gifts_19952026 (1)'!$E:$E,'AHCF_Gifts_19952026 (1)'!$D:$D,">="&DATE($B23-1,7,1),'AHCF_Gifts_19952026 (1)'!$D:$D,"<="&DATE($B23,6,30)) -> 820822.16 | D23: =COUNTIFS('AHCF_Gifts_19952026 (1)'!$D:$D,">="&DATE($B23-1,7,1),'AHCF_Gifts_19952026 (1)'!$D:$D,"<="&DATE($B23,6,30)) -> 1631 | N23: ="FY"&B23 -> FY2012
B24: =B23+1 -> 2013 | C24: =SUMIFS('AHCF_Gifts_19952026 (1)'!$E:$E,'AHCF_Gifts_19952026 (1)'!$D:$D,">="&DATE($B24-1,7,1),'AHCF_Gifts_19952026 (1)'!$D:$D,"<="&DATE($B24,6,30)) -> 11730012 | D24: =COUNTIFS('AHCF_Gifts_19952026 (1)'!$D:$D,">="&DATE($B24-1,7,1),'AHCF_Gifts_19952026 (1)'!$D:$D,"<="&DATE($B24,6,30)) -> 1571 | N24: ="FY"&B24 -> FY2013
B25: =B24+1 -> 2014 | C25: =SUMIFS('AHCF_Gifts_19952026 (1)'!$E:$E,'AHCF_Gifts_19952026 (1)'!$D:$D,">="&DATE($B25-1,7,1),'AHCF_Gifts_19952026 (1)'!$D:$D,"<="&DATE($B25,6,30)) -> 4260256.7 | D25: =COUNTIFS('AHCF_Gifts_19952026 (1)'!$D:$D,">="&DATE($B25-1,7,1),'AHCF_Gifts_19952026 (1)'!$D:$D,"<="&DATE($B25,6,30)) -> 1525 | N25: ="FY"&B25 -> FY2014
B26: =B25+1 -> 2015 | C26: =SUMIFS('AHCF_Gifts_19952026 (1)'!$E:$E,'AHCF_Gifts_19952026 (1)'!$D:$D,">="&DATE($B26-1,7,1),'AHCF_Gifts_19952026 (1)'!$D:$D,"<="&DATE($B26,6,30)) -> 1408187.6 | D26: =COUNTIFS('AHCF_Gifts_19952026 (1)'!$D:$D,">="&DATE($B26-1,7,1),'AHCF_Gifts_19952026 (1)'!$D:$D,"<="&DATE($B26,6,30)) -> 2125 | K26: Tier | L26: # of Gifts | N26: ="FY"&B26 -> FY2015
B27: =B26+1 -> 2016 | C27: =SUMIFS('AHCF_Gifts_19952026 (1)'!$E:$E,'AHCF_Gifts_19952026 (1)'!$D:$D,">="&DATE($B27-1,7,1),'AHCF_Gifts_19952026 (1)'!$D:$D,"<="&DATE($B27,6,30)) -> 1752133.7 | D27: =COUNTIFS('AHCF_Gifts_19952026 (1)'!$D:$D,">="&DATE($B27-1,7,1),'AHCF_Gifts_19952026 (1)'!$D:$D,"<="&DATE($B27,6,30)) -> 2132 | K27: =B8 -> $25,000 + | L27: =E8 -> 9 | N27: ="FY"&B27 -> FY2016
B28: =B27+1 -> 2017 | C28: =SUMIFS('AHCF_Gifts_19952026 (1)'!$E:$E,'AHCF_Gifts_19952026 (1)'!$D:$D,">="&DATE($B28-1,7,1),'AHCF_Gifts_19952026 (1)'!$D:$D,"<="&DATE($B28,6,30)) -> 1228110.1 | D28: =COUNTIFS('AHCF_Gifts_19952026 (1)'!$D:$D,">="&DATE($B28-1,7,1),'AHCF_Gifts_19952026 (1)'!$D:$D,"<="&DATE($B28,6,30)) -> 1933 | K28: =B9 -> $10,000 – $24,999 | L28: =E9 -> 33 | N28: ="FY"&B28 -> FY2017
B29: =B28+1 -> 2018 | C29: =SUMIFS('AHCF_Gifts_19952026 (1)'!$E:$E,'AHCF_Gifts_19952026 (1)'!$D:$D,">="&DATE($B29-1,7,1),'AHCF_Gifts_19952026 (1)'!$D:$D,"<="&DATE($B29,6,30)) -> 3878534.5 | D29: =COUNTIFS('AHCF_Gifts_19952026 (1)'!$D:$D,">="&DATE($B29-1,7,1),'AHCF_Gifts_19952026 (1)'!$D:$D,"<="&DATE($B29,6,30)) -> 2101 | K29: =B10 -> $5,000 – $9,999 | L29: =E10 -> 39 | N29: ="FY"&B29 -> FY2018
B30: =B29+1 -> 2019 | C30: =SUMIFS('AHCF_Gifts_19952026 (1)'!$E:$E,'AHCF_Gifts_19952026 (1)'!$D:$D,">="&DATE($B30-1,7,1),'AHCF_Gifts_19952026 (1)'!$D:$D,"<="&DATE($B30,6,30)) -> 2136157 | D30: =COUNTIFS('AHCF_Gifts_19952026 (1)'!$D:$D,">="&DATE($B30-1,7,1),'AHCF_Gifts_19952026 (1)'!$D:$D,"<="&DATE($B30,6,30)) -> 2176 | K30: =B11 -> $2,500 – $4,999 | L30: =E11 -> 34 | N30: ="FY"&B30 -> FY2019
B31: =B30+1 -> 2020 | C31: =SUMIFS('AHCF_Gifts_19952026 (1)'!$E:$E,'AHCF_Gifts_19952026 (1)'!$D:$D,">="&DATE($B31-1,7,1),'AHCF_Gifts_19952026 (1)'!$D:$D,"<="&DATE($B31,6,30)) -> 3808669.7 | D31: =COUNTIFS('AHCF_Gifts_19952026 (1)'!$D:$D,">="&DATE($B31-1,7,1),'AHCF_Gifts_19952026 (1)'!$D:$D,"<="&DATE($B31,6,30)) -> 2286 | K31: =B12 -> $1,000 – $2,499 | L31: =E12 -> 142 | N31: ="FY"&B31 -> FY2020
B32: =B31+1 -> 2021 | C32: =SUMIFS('AHCF_Gifts_19952026 (1)'!$E:$E,'AHCF_Gifts_19952026 (1)'!$D:$D,">="&DATE($B32-1,7,1),'AHCF_Gifts_19952026 (1)'!$D:$D,"<="&DATE($B32,6,30)) -> 2847023.3 | D32: =COUNTIFS('AHCF_Gifts_19952026 (1)'!$D:$D,">="&DATE($B32-1,7,1),'AHCF_Gifts_19952026 (1)'!$D:$D,"<="&DATE($B32,6,30)) -> 2988 | K32: =B13 -> $500 – $999 | L32: =E13 -> 106 | N32: ="FY"&B32 -> FY2021
B33: =B32+1 -> 2022 | C33: =SUMIFS('AHCF_Gifts_19952026 (1)'!$E:$E,'AHCF_Gifts_19952026 (1)'!$D:$D,">="&DATE($B33-1,7,1),'AHCF_Gifts_19952026 (1)'!$D:$D,"<="&DATE($B33,6,30)) -> 2443105.9 | D33: =COUNTIFS('AHCF_Gifts_19952026 (1)'!$D:$D,">="&DATE($B33-1,7,1),'AHCF_Gifts_19952026 (1)'!$D:$D,"<="&DATE($B33,6,30)) -> 2826 | K33: =B14 -> $250 – $499 | L33: =E14 -> 95 | N33: ="FY"&B33 -> FY2022
B34: =B33+1 -> 2023 | C34: =SUMIFS('AHCF_Gifts_19952026 (1)'!$E:$E,'AHCF_Gifts_19952026 (1)'!$D:$D,">="&DATE($B34-1,7,1),'AHCF_Gifts_19952026 (1)'!$D:$D,"<="&DATE($B34,6,30)) -> 1360029.8 | D34: =COUNTIFS('AHCF_Gifts_19952026 (1)'!$D:$D,">="&DATE($B34-1,7,1),'AHCF_Gifts_19952026 (1)'!$D:$D,"<="&DATE($B34,6,30)) -> 2708 | K34: =B15 -> $100 – $249 | L34: =E15 -> 331 | N34: ="FY"&B34 -> FY2023
B35: =B34+1 -> 2024 | C35: =SUMIFS('AHCF_Gifts_19952026 (1)'!$E:$E,'AHCF_Gifts_19952026 (1)'!$D:$D,">="&DATE($B35-1,7,1),'AHCF_Gifts_19952026 (1)'!$D:$D,"<="&DATE($B35,6,30)) -> 3169714.5 | D35: =COUNTIFS('AHCF_Gifts_19952026 (1)'!$D:$D,">="&DATE($B35-1,7,1),'AHCF_Gifts_19952026 (1)'!$D:$D,"<="&DATE($B35,6,30)) -> 2465 | K35: =B16 -> Under $100 | L35: =E16 -> 1540 | N35: ="FY"&B35 -> FY2024
B36: =B35+1 -> 2025 | C36: =SUMIFS('AHCF_Gifts_19952026 (1)'!$E:$E,'AHCF_Gifts_19952026 (1)'!$D:$D,">="&DATE($B36-1,7,1),'AHCF_Gifts_19952026 (1)'!$D:$D,"<="&DATE($B36,6,30)) -> 1559426 | D36: =COUNTIFS('AHCF_Gifts_19952026 (1)'!$D:$D,">="&DATE($B36-1,7,1),'AHCF_Gifts_19952026 (1)'!$D:$D,"<="&DATE($B36,6,30)) -> 2337 | N36: ="FY"&B36 -> FY2025
B37: =B36+1 -> 2026 | C37: =SUMIFS('AHCF_Gifts_19952026 (1)'!$E:$E,'AHCF_Gifts_19952026 (1)'!$D:$D,">="&DATE($B37-1,7,1),'AHCF_Gifts_19952026 (1)'!$D:$D,"<="&DATE($B37,6,30)) -> 1768709.3 | D37: =COUNTIFS('AHCF_Gifts_19952026 (1)'!$D:$D,">="&DATE($B37-1,7,1),'AHCF_Gifts_19952026 (1)'!$D:$D,"<="&DATE($B37,6,30)) -> 2373 | N37: ="FY"&B37 -> FY2026

Sheet Donor Retention
B2: Donor Retention
B3: Retention rate = share of the prior fiscal year's unique donors (by Constituent ID) who gave again the following year. Fiscal year = Jul–Jun.
B5: Fiscal Year | C5: Active Donors | D5: Prior-Yr Donors | E5: Retained Donors | F5: Retention Rate | G5: New / Reactivated
B6: 2011 | C6: =SUM(INDEX('Retention Calc'!$B$2:$Q$2698,0,MATCH($B6,'Retention Calc'!$B$1:$Q$1,0))) -> 337 | D6: =IFERROR(SUM(INDEX('Retention Calc'!$B$2:$Q$2698,0,MATCH($B6-1,'Retention Calc'!$B$1:$Q$1,0))),"") | E6: =IFERROR(SUMPRODUCT(INDEX('Retention Calc'!$B$2:$Q$2698,0,MATCH($B6,'Retention Calc'!$B$1:$Q$1,0)),INDEX('Retention Calc'!$B$2:$Q$2698,0,MATCH($B6-1,'Retention Calc'!$B$1:$Q$1,0))),"") | F6: =IFERROR(E6/D6,"") | G6: =IF(E6="",C6,C6-E6) -> 337 | T6: ="FY"&B6 -> FY2011
B7: =B6+1 -> 2012 | C7: =SUM(INDEX('Retention Calc'!$B$2:$Q$2698,0,MATCH($B7,'Retention Calc'!$B$1:$Q$1,0))) -> 340 | D7: =IFERROR(SUM(INDEX('Retention Calc'!$B$2:$Q$2698,0,MATCH($B7-1,'Retention Calc'!$B$1:$Q$1,0))),"") -> 337 | E7: =IFERROR(SUMPRODUCT(INDEX('Retention Calc'!$B$2:$Q$2698,0,MATCH($B7,'Retention Calc'!$B$1:$Q$1,0)),INDEX('Retention Calc'!$B$2:$Q$2698,0,MATCH($B7-1,'Retention Calc'!$B$1:$Q$1,0))),"") -> 176 | F7: =IFERROR(E7/D7,"") -> 0.52225519 | G7: =IF(E7="",C7,C7-E7) -> 164 | T7: ="FY"&B7 -> FY2012
B8: =B7+1 -> 2013 | C8: =SUM(INDEX('Retention Calc'!$B$2:$Q$2698,0,MATCH($B8,'Retention Calc'!$B$1:$Q$1,0))) -> 357 | D8: =IFERROR(SUM(INDEX('Retention Calc'!$B$2:$Q$2698,0,MATCH($B8-1,'Retention Calc'!$B$1:$Q$1,0))),"") -> 340 | E8: =IFERROR(SUMPRODUCT(INDEX('Retention Calc'!$B$2:$Q$2698,0,MATCH($B8,'Retention Calc'!$B$1:$Q$1,0)),INDEX('Retention Calc'!$B$2:$Q$2698,0,MATCH($B8-1,'Retention Calc'!$B$1:$Q$1,0))),"") -> 193 | F8: =IFERROR(E8/D8,"") -> 0.56764706 | G8: =IF(E8="",C8,C8-E8) -> 164 | T8: ="FY"&B8 -> FY2013
B9: =B8+1 -> 2014 | C9: =SUM(INDEX('Retention Calc'!$B$2:$Q$2698,0,MATCH($B9,'Retention Calc'!$B$1:$Q$1,0))) -> 365 | D9: =IFERROR(SUM(INDEX('Retention Calc'!$B$2:$Q$2698,0,MATCH($B9-1,'Retention Calc'!$B$1:$Q$1,0))),"") -> 357 | E9: =IFERROR(SUMPRODUCT(INDEX('Retention Calc'!$B$2:$Q$2698,0,MATCH($B9,'Retention Calc'!$B$1:$Q$1,0)),INDEX('Retention Calc'!$B$2:$Q$2698,0,MATCH($B9-1,'Retention Calc'!$B$1:$Q$1,0))),"") -> 221 | F9: =IFERROR(E9/D9,"") -> 0.61904762 | G9: =IF(E9="",C9,C9-E9) -> 144 | T9: ="FY"&B9 -> FY2014
B10: =B9+1 -> 2015 | C10: =SUM(INDEX('Retention Calc'!$B$2:$Q$2698,0,MATCH($B10,'Retention Calc'!$B$1:$Q$1,0))) -> 440 | D10: =IFERROR(SUM(INDEX('Retention Calc'!$B$2:$Q$2698,0,MATCH($B10-1,'Retention Calc'!$B$1:$Q$1,0))),"") -> 365 | E10: =IFERROR(SUMPRODUCT(INDEX('Retention Calc'!$B$2:$Q$2698,0,MATCH($B10,'Retention Calc'!$B$1:$Q$1,0)),INDEX('Retention Calc'!$B$2:$Q$2698,0,MATCH($B10-1,'Retention Calc'!$B$1:$Q$1,0))),"") -> 239 | F10: =IFERROR(E10/D10,"") -> 0.65479452 | G10: =IF(E10="",C10,C10-E10) -> 201 | T10: ="FY"&B10 -> FY2015
B11: =B10+1 -> 2016 | C11: =SUM(INDEX('Retention Calc'!$B$2:$Q$2698,0,MATCH($B11,'Retention Calc'!$B$1:$Q$1,0))) -> 482 | D11: =IFERROR(SUM(INDEX('Retention Calc'!$B$2:$Q$2698,0,MATCH($B11-1,'Retention Calc'!$B$1:$Q$1,0))),"") -> 440 | E11: =IFERROR(SUMPRODUCT(INDEX('Retention Calc'!$B$2:$Q$2698,0,MATCH($B11,'Retention Calc'!$B$1:$Q$1,0)),INDEX('Retention Calc'!$B$2:$Q$2698,0,MATCH($B11-1,'Retention Calc'!$B$1:$Q$1,0))),"") -> 264 | F11: =IFERROR(E11/D11,"") -> 0.6 | G11: =IF(E11="",C11,C11-E11) -> 218 | T11: ="FY"&B11 -> FY2016
B12: =B11+1 -> 2017 | C12: =SUM(INDEX('Retention Calc'!$B$2:$Q$2698,0,MATCH($B12,'Retention Calc'!$B$1:$Q$1,0))) -> 521 | D12: =IFERROR(SUM(INDEX('Retention Calc'!$B$2:$Q$2698,0,MATCH($B12-1,'Retention Calc'!$B$1:$Q$1,0))),"") -> 482 | E12: =IFERROR(SUMPRODUCT(INDEX('Retention Calc'!$B$2:$Q$2698,0,MATCH($B12,'Retention Calc'!$B$1:$Q$1,0)),INDEX('Retention Calc'!$B$2:$Q$2698,0,MATCH($B12-1,'Retention Calc'!$B$1:$Q$1,0))),"") -> 263 | F12: =IFERROR(E12/D12,"") -> 0.54564315 | G12: =IF(E12="",C12,C12-E12) -> 258 | T12: ="FY"&B12 -> FY2017
B13: =B12+1 -> 2018 | C13: =SUM(INDEX('Retention Calc'!$B$2:$Q$2698,0,MATCH($B13,'Retention Calc'!$B$1:$Q$1,0))) -> 456 | D13: =IFERROR(SUM(INDEX('Retention Calc'!$B$2:$Q$2698,0,MATCH($B13-1,'Retention Calc'!$B$1:$Q$1,0))),"") -> 521 | E13: =IFERROR(SUMPRODUCT(INDEX('Retention Calc'!$B$2:$Q$2698,0,MATCH($B13,'Retention Calc'!$B$1:$Q$1,0)),INDEX('Retention Calc'!$B$2:$Q$2698,0,MATCH($B13-1,'Retention Calc'!$B$1:$Q$1,0))),"") -> 269 | F13: =IFERROR(E13/D13,"") -> 0.51631478 | G13: =IF(E13="",C13,C13-E13) -> 187 | T13: ="FY"&B13 -> FY2018
B14: =B13+1 -> 2019 | C14: =SUM(INDEX('Retention Calc'!$B$2:$Q$2698,0,MATCH($B14,'Retention Calc'!$B$1:$Q$1,0))) -> 439 | D14: =IFERROR(SUM(INDEX('Retention Calc'!$B$2:$Q$2698,0,MATCH($B14-1,'Retention Calc'!$B$1:$Q$1,0))),"") -> 456 | E14: =IFERROR(SUMPRODUCT(INDEX('Retention Calc'!$B$2:$Q$2698,0,MATCH($B14,'Retention Calc'!$B$1:$Q$1,0)),INDEX('Retention Calc'!$B$2:$Q$2698,0,MATCH($B14-1,'Retention Calc'!$B$1:$Q$1,0))),"") -> 259 | F14: =IFERROR(E14/D14,"") -> 0.56798246 | G14: =IF(E14="",C14,C14-E14) -> 180 | T14: ="FY"&B14 -> FY2019
B15: =B14+1 -> 2020 | C15: =SUM(INDEX('Retention Calc'!$B$2:$Q$2698,0,MATCH($B15,'Retention Calc'!$B$1:$Q$1,0))) -> 464 | D15: =IFERROR(SUM(INDEX('Retention Calc'!$B$2:$Q$2698,0,MATCH($B15-1,'Retention Calc'!$B$1:$Q$1,0))),"") -> 439 | E15: =IFERROR(SUMPRODUCT(INDEX('Retention Calc'!$B$2:$Q$2698,0,MATCH($B15,'Retention Calc'!$B$1:$Q$1,0)),INDEX('Retention Calc'!$B$2:$Q$2698,0,MATCH($B15-1,'Retention Calc'!$B$1:$Q$1,0))),"") -> 219 | F15: =IFERROR(E15/D15,"") -> 0.49886105 | G15: =IF(E15="",C15,C15-E15) -> 245 | T15: ="FY"&B15 -> FY2020
B16: =B15+1 -> 2021 | C16: =SUM(INDEX('Retention Calc'!$B$2:$Q$2698,0,MATCH($B16,'Retention Calc'!$B$1:$Q$1,0))) -> 546 | D16: =IFERROR(SUM(INDEX('Retention Calc'!$B$2:$Q$2698,0,MATCH($B16-1,'Retention Calc'!$B$1:$Q$1,0))),"") -> 464 | E16: =IFERROR(SUMPRODUCT(INDEX('Retention Calc'!$B$2:$Q$2698,0,MATCH($B16,'Retention Calc'!$B$1:$Q$1,0)),INDEX('Retention Calc'!$B$2:$Q$2698,0,MATCH($B16-1,'Retention Calc'!$B$1:$Q$1,0))),"") -> 262 | F16: =IFERROR(E16/D16,"") -> 0.56465517 | G16: =IF(E16="",C16,C16-E16) -> 284 | T16: ="FY"&B16 -> FY2021
B17: =B16+1 -> 2022 | C17: =SUM(INDEX('Retention Calc'!$B$2:$Q$2698,0,MATCH($B17,'Retention Calc'!$B$1:$Q$1,0))) -> 525 | D17: =IFERROR(SUM(INDEX('Retention Calc'!$B$2:$Q$2698,0,MATCH($B17-1,'Retention Calc'!$B$1:$Q$1,0))),"") -> 546 | E17: =IFERROR(SUMPRODUCT(INDEX('Retention Calc'!$B$2:$Q$2698,0,MATCH($B17,'Retention Calc'!$B$1:$Q$1,0)),INDEX('Retention Calc'!$B$2:$Q$2698,0,MATCH($B17-1,'Retention Calc'!$B$1:$Q$1,0))),"") -> 297 | F17: =IFERROR(E17/D17,"") -> 0.54395604 | G17: =IF(E17="",C17,C17-E17) -> 228 | T17: ="FY"&B17 -> FY2022
B18: =B17+1 -> 2023 | C18: =SUM(INDEX('Retention Calc'!$B$2:$Q$2698,0,MATCH($B18,'Retention Calc'!$B$1:$Q$1,0))) -> 537 | D18: =IFERROR(SUM(INDEX('Retention Calc'!$B$2:$Q$2698,0,MATCH($B18-1,'Retention Calc'!$B$1:$Q$1,0))),"") -> 525 | E18: =IFERROR(SUMPRODUCT(INDEX('Retention Calc'!$B$2:$Q$2698,0,MATCH($B18,'Retention Calc'!$B$1:$Q$1,0)),INDEX('Retention Calc'!$B$2:$Q$2698,0,MATCH($B18-1,'Retention Calc'!$B$1:$Q$1,0))),"") -> 304 | F18: =IFERROR(E18/D18,"") -> 0.57904762 | G18: =IF(E18="",C18,C18-E18) -> 233 | T18: ="FY"&B18 -> FY2023
... B21: =B20+1 -> 2026 | C21: =SUM(INDEX('Retention Calc'!$B$2:$Q$2698,0,MATCH($B21,'Retention Calc'!$B$1:$Q$1,0))) -> 546 | D21: =IFERROR(SUM(INDEX('Retention Calc'!$B$2:$Q$2698,0,MATCH($B21-1,'Retention Calc'!$B$1:$Q$1,0))),"") -> 535 | E21: =IFERROR(SUMPRODUCT(INDEX('Retention Calc'!$B$2:$Q$2698,0,MATCH($B21,'Retention Calc'!$B$1:$Q$1,0)),INDEX('Retention Calc'!$B$2:$Q$2698,0,MATCH($B21-1,'Retention Calc'!$B$1:$Q$1,0))),"") -> 296 | F21: =IFERROR(E21/D21,"") -> 0.55327103 | G21: =IF(E21="",C21,C21-E21) -> 250 | T21: ="FY"&B21 -> FY2026
B24: Cohort Retention — % of Acquisition Cohort Still Giving
B25: Donors grouped by fiscal year of their FIRST gift. Each cell = % of that cohort who gave in a later year. Year 0 = 100% by definition.
B26: Cohort | C26: Donors | D26: 0 | E26: 1 | F26: 2 | G26: 3 | H26: 4 | I26: 5 | J26: 6 | K26: 7 | L26: 8 | M26: 9 | N26: 10 | O26: 11 | P26: 12 | Q26: 13 | R26: 14 | S26: 15 | V26: Years since | W26: ="FY"&B27 -> FY2011 | X26: ="FY"&B28 -> FY2012 | Y26: ="FY"&B29 -> FY2013 | Z26: ="FY"&B30 -> FY2014 | AA26: ="FY"&B31 -> FY2015 | AB26: ="FY"&B32 -> FY2016 | AC26: ="FY"&B33 -> FY2017 | AD26: ="FY"&B34 -> FY2018 | AE26: ="FY"&B35 -> FY2019 | AF26: ="FY"&B36 -> FY2020 | AG26: ="FY"&B37 -> FY2021 | AH26: ="FY"&B38 -> FY2022 | AI26: ="FY"&B39 -> FY2023 | AJ26: ="FY"&B40 -> FY2024 | AK26: ="FY"&B41 -> FY2025 | AL26: ="FY"&B42 -> FY2026 | AM26: Blended
B27: 2011 | C27: =COUNTIF('Retention Calc'!$R$2:$R$2698,$B27) -> 337 | D27: {=IFERROR(IF($B27+D$26>2026,"",SUMPRODUCT(('Retention Calc'!$R$2:$R$2698=$B27)*INDEX('Retention Calc'!$B$2:$Q$2698,0,MATCH($B27+D$26,'Retention Calc'!$B$1:$Q$1,0)))/$C27),"")} -> 1 | E27: {=IFERROR(IF($B27+E$26>2026,"",SUMPRODUCT(('Retention Calc'!$R$2:$R$2698=$B27)*INDEX('Retention Calc'!$B$2:$Q$2698,0,MATCH($B27+E$26,'Retention Calc'!$B$1:$Q$1,0)))/$C27),"")} -> 0.52225519 | F27: {=IFERROR(IF($B27+F$26>2026,"",SUMPRODUCT(('Retention Calc'!$R$2:$R$2698=$B27)*INDEX('Retention Calc'!$B$2:$Q$2698,0,MATCH($B27+F$26,'Retention Calc'!$B$1:$Q$1,0)))/$C27),"")} -> 0.50148368 | G27: {=IFERROR(IF($B27+G$26>2026,"",SUMPRODUCT(('Retention Calc'!$R$2:$R$2698=$B27)*INDEX('Retention Calc'!$B$2:$Q$2698,0,MATCH($B27+G$26,'Retention Calc'!$B$1:$Q$1,0)))/$C27),"")} -> 0.45697329 | H27: {=IFERROR(IF($B27+H$26>2026,"",SUMPRODUCT(('Retention Calc'!$R$2:$R$2698=$B27)*INDEX('Retention Calc'!$B$2:$Q$2698,0,MATCH($B27+H$26,'Retention Calc'!$B$1:$Q$1,0)))/$C27),"")} -> 0.47477745 | I27: {=IFERROR(IF($B27+I$26>2026,"",SUMPRODUCT(('Retention Calc'!$R$2:$R$2698=$B27)*INDEX('Retention Calc'!$B$2:$Q$2698,0,MATCH($B27+I$26,'Retention Calc'!$B$1:$Q$1,0)))/$C27),"")} -> 0.44807122 | J27: {=IFERROR(IF($B27+J$26>2026,"",SUMPRODUCT(('Retention Calc'!$R$2:$R$2698=$B27)*INDEX('Retention Calc'!$B$2:$Q$2698,0,MATCH($B27+J$26,'Retention Calc'!$B$1:$Q$1,0)))/$C27),"")} -> 0.39762611 | K27: {=IFERROR(IF($B27+K$26>2026,"",SUMPRODUCT(('Retention Calc'!$R$2:$R$2698=$B27)*INDEX('Retention Calc'!$B$2:$Q$2698,0,MATCH($B27+K$26,'Retention Calc'!$B$1:$Q$1,0)))/$C27),"")} -> 0.38278932 | ... S27: {=IFERROR(IF($B27+S$26>2026,"",SUMPRODUCT(('Retention Calc'!$R$2:$R$2698=$B27)*INDEX('Retention Calc'!$B$2:$Q$2698,0,MATCH($B27+S$26,'Retention Calc'!$B$1:$Q$1,0)))/$C27),"")} -> 0.22255193 | V27: ="Year "&0 -> Year 0 | W27: =IF(D27="",NA(),D27) -> 1 | X27: =IF(D28="",NA(),D28) -> 1 | Y27: =IF(D29="",NA(),D29) -> 1 | Z27: =IF(D30="",NA(),D30) -> 1 | AA27: =IF(D31="",NA(),D31) -> 1 | AB27: =IF(D32="",NA(),D32) -> 1 | AC27: =IF(D33="",NA(),D33) -> 1 | AD27: =IF(D34="",NA(),D34) -> 1 | AE27: =IF(D35="",NA(),D35) -> 1 | AF27: =IF(D36="",NA(),D36) -> 1 | AG27: =IF(D37="",NA(),D37) -> 1 | AH27: =IF(D38="",NA(),D38) -> 1 | AI27: =IF(D39="",NA(),D39) -> 1 | AJ27: =IF(D40="",NA(),D40) -> 1 | AK27: =IF(D41="",NA(),D41) -> 1 | AL27: =IF(D42="",NA(),D42) -> 1 | AM27: =IF(D43="",NA(),D43) -> 1 | AN27: ="FY"&B27 -> FY2011
B28: =B27+1 -> 2012 | C28: =COUNTIF('Retention Calc'!$R$2:$R$2698,$B28) -> 164 | D28: {=IFERROR(IF($B28+D$26>2026,"",SUMPRODUCT(('Retention Calc'!$R$2:$R$2698=$B28)*INDEX('Retention Calc'!$B$2:$Q$2698,0,MATCH($B28+D$26,'Retention Calc'!$B$1:$Q$1,0)))/$C28),"")} -> 1 | E28: {=IFERROR(IF($B28+E$26>2026,"",SUMPRODUCT(('Retention Calc'!$R$2:$R$2698=$B28)*INDEX('Retention Calc'!$B$2:$Q$2698,0,MATCH($B28+E$26,'Retention Calc'!$B$1:$Q$1,0)))/$C28),"")} -> 0.32317073 | F28: {=IFERROR(IF($B28+F$26>2026,"",SUMPRODUCT(('Retention Calc'!$R$2:$R$2698=$B28)*INDEX('Retention Calc'!$B$2:$Q$2698,0,MATCH($B28+F$26,'Retention Calc'!$B$1:$Q$1,0)))/$C28),"")} -> 0.31707317 | G28: {=IFERROR(IF($B28+G$26>2026,"",SUMPRODUCT(('Retention Calc'!$R$2:$R$2698=$B28)*INDEX('Retention Calc'!$B$2:$Q$2698,0,MATCH($B28+G$26,'Retention Calc'!$B$1:$Q$1,0)))/$C28),"")} -> 0.32317073 | H28: {=IFERROR(IF($B28+H$26>2026,"",SUMPRODUCT(('Retention Calc'!$R$2:$R$2698=$B28)*INDEX('Retention Calc'!$B$2:$Q$2698,0,MATCH($B28+H$26,'Retention Calc'!$B$1:$Q$1,0)))/$C28),"")} -> 0.29268293 | I28: {=IFERROR(IF($B28+I$26>2026,"",SUMPRODUCT(('Retention Calc'!$R$2:$R$2698=$B28)*INDEX('Retention Calc'!$B$2:$Q$2698,0,MATCH($B28+I$26,'Retention Calc'!$B$1:$Q$1,0)))/$C28),"")} -> 0.2804878 | J28: {=IFERROR(IF($B28+J$26>2026,"",SUMPRODUCT(('Retention Calc'!$R$2:$R$2698=$B28)*INDEX('Retention Calc'!$B$2:$Q$2698,0,MATCH($B28+J$26,'Retention Calc'!$B$1:$Q$1,0)))/$C28),"")} -> 0.24390244 | K28: {=IFERROR(IF($B28+K$26>2026,"",SUMPRODUCT(('Retention Calc'!$R$2:$R$2698=$B28)*INDEX('Retention Calc'!$B$2:$Q$2698,0,MATCH($B28+K$26,'Retention Calc'!$B$1:$Q$1,0)))/$C28),"")} -> 0.20121951 | ... S28: {=IFERROR(IF($B28+S$26>2026,"",SUMPRODUCT(('Retention Calc'!$R$2:$R$2698=$B28)*INDEX('Retention Calc'!$B$2:$Q$2698,0,MATCH($B28+S$26,'Retention Calc'!$B$1:$Q$1,0)))/$C28),"")} | V28: ="Year "&1 -> Year 1 | W28: =IF(E27="",NA(),E27) -> 0.52225519 | X28: =IF(E28="",NA(),E28) -> 0.32317073 | Y28: =IF(E29="",NA(),E29) -> 0.34814815 | Z28: =IF(E30="",NA(),E30) -> 0.33035714 | AA28: =IF(E31="",NA(),E31) -> 0.27333333 | AB28: =IF(E32="",NA(),E32) -> 0.18023256 | AC28: =IF(E33="",NA(),E33) -> 0.20754717 | AD28: =IF(E34="",NA(),E34) -> 0.21774194 | AE28: =IF(E35="",NA(),E35) -> 0.084507042 | AF28: =IF(E36="",NA(),E36) -> 0.24691358 | AG28: =IF(E37="",NA(),E37) -> 0.21808511 | AH28: =IF(E38="",NA(),E38) -> 0.31318681 | AI28: =IF(E39="",NA(),E39) -> 0.28571429 | AJ28: =IF(E40="",NA(),E40) -> 0.30081301 | AK28: =IF(E41="",NA(),E41) -> 0.19875776 | AL28: =IF(E42="",NA(),E42) -> #N/A | AM28: =IF(E43="",NA(),E43) -> 0.28554502 | AN28: ="FY"&B28 -> FY2012
B29: =B28+1 -> 2013 | C29: =COUNTIF('Retention Calc'!$R$2:$R$2698,$B29) -> 135 | D29: {=IFERROR(IF($B29+D$26>2026,"",SUMPRODUCT(('Retention Calc'!$R$2:$R$2698=$B29)*INDEX('Retention Calc'!$B$2:$Q$2698,0,MATCH($B29+D$26,'Retention Calc'!$B$1:$Q$1,0)))/$C29),"")} -> 1 | E29: {=IFERROR(IF($B29+E$26>2026,"",SUMPRODUCT(('Retention Calc'!$R$2:$R$2698=$B29)*INDEX('Retention Calc'!$B$2:$Q$2698,0,MATCH($B29+E$26,'Retention Calc'!$B$1:$Q$1,0)))/$C29),"")} -> 0.34814815 | F29: {=IFERROR(IF($B29+F$26>2026,"",SUMPRODUCT(('Retention Calc'!$R$2:$R$2698=$B29)*INDEX('Retention Calc'!$B$2:$Q$2698,0,MATCH($B29+F$26,'Retention Calc'!$B$1:$Q$1,0)))/$C29),"")} -> 0.2962963 | G29: {=IFERROR(IF($B29+G$26>2026,"",SUMPRODUCT(('Retention Calc'!$R$2:$R$2698=$B29)*INDEX('Retention Calc'!$B$2:$Q$2698,0,MATCH($B29+G$26,'Retention Calc'!$B$1:$Q$1,0)))/$C29),"")} -> 0.27407407 | H29: {=IFERROR(IF($B29+H$26>2026,"",SUMPRODUCT(('Retention Calc'!$R$2:$R$2698=$B29)*INDEX('Retention Calc'!$B$2:$Q$2698,0,MATCH($B29+H$26,'Retention Calc'!$B$1:$Q$1,0)))/$C29),"")} -> 0.27407407 | I29: {=IFERROR(IF($B29+I$26>2026,"",SUMPRODUCT(('Retention Calc'!$R$2:$R$2698=$B29)*INDEX('Retention Calc'!$B$2:$Q$2698,0,MATCH($B29+I$26,'Retention Calc'!$B$1:$Q$1,0)))/$C29),"")} -> 0.23703704 | J29: {=IFERROR(IF($B29+J$26>2026,"",SUMPRODUCT(('Retention Calc'!$R$2:$R$2698=$B29)*INDEX('Retention Calc'!$B$2:$Q$2698,0,MATCH($B29+J$26,'Retention Calc'!$B$1:$Q$1,0)))/$C29),"")} -> 0.17777778 | K29: {=IFERROR(IF($B29+K$26>2026,"",SUMPRODUCT(('Retention Calc'!$R$2:$R$2698=$B29)*INDEX('Retention Calc'!$B$2:$Q$2698,0,MATCH($B29+K$26,'Retention Calc'!$B$1:$Q$1,0)))/$C29),"")} -> 0.15555556 | ... S29: {=IFERROR(IF($B29+S$26>2026,"",SUMPRODUCT(('Retention Calc'!$R$2:$R$2698=$B29)*INDEX('Retention Calc'!$B$2:$Q$2698,0,MATCH($B29+S$26,'Retention Calc'!$B$1:$Q$1,0)))/$C29),"")} | V29: ="Year "&2 -> Year 2 | W29: =IF(F27="",NA(),F27) -> 0.50148368 | X29: =IF(F28="",NA(),F28) -> 0.31707317 | Y29: =IF(F29="",NA(),F29) -> 0.2962963 | Z29: =IF(F30="",NA(),F30) -> 0.29464286 | AA29: =IF(F31="",NA(),F31) -> 0.22666667 | AB29: =IF(F32="",NA(),F32) -> 0.15116279 | AC29: =IF(F33="",NA(),F33) -> 0.13679245 | AD29: =IF(F34="",NA(),F34) -> 0.22580645 | AE29: =IF(F35="",NA(),F35) -> 0.13380282 | AF29: =IF(F36="",NA(),F36) -> 0.17283951 | AG29: =IF(F37="",NA(),F37) -> 0.20212766 | AH29: =IF(F38="",NA(),F38) -> 0.1978022 | AI29: =IF(F39="",NA(),F39) -> 0.18452381 | AJ29: =IF(F40="",NA(),F40) -> 0.2601626 | AK29: =IF(F41="",NA(),F41) -> #N/A | AL29: =IF(F42="",NA(),F42) -> #N/A | AM29: =IF(F43="",NA(),F43) -> 0.25094897 | AN29: ="FY"&B29 -> FY2013
B30: =B29+1 -> 2014 | C30: =COUNTIF('Retention Calc'!$R$2:$R$2698,$B30) -> 112 | D30: {=IFERROR(IF($B30+D$26>2026,"",SUMPRODUCT(('Retention Calc'!$R$2:$R$2698=$B30)*INDEX('Retention Calc'!$B$2:$Q$2698,0,MATCH($B30+D$26,'Retention Calc'!$B$1:$Q$1,0)))/$C30),"")} -> 1 | E30: {=IFERROR(IF($B30+E$26>2026,"",SUMPRODUCT(('Retention Calc'!$R$2:$R$2698=$B30)*INDEX('Retention Calc'!$B$2:$Q$2698,0,MATCH($B30+E$26,'Retention Calc'!$B$1:$Q$1,0)))/$C30),"")} -> 0.33035714 | F30: {=IFERROR(IF($B30+F$26>2026,"",SUMPRODUCT(('Retention Calc'!$R$2:$R$2698=$B30)*INDEX('Retention Calc'!$B$2:$Q$2698,0,MATCH($B30+F$26,'Retention Calc'!$B$1:$Q$1,0)))/$C30),"")} -> 0.29464286 | G30: {=IFERROR(IF($B30+G$26>2026,"",SUMPRODUCT(('Retention Calc'!$R$2:$R$2698=$B30)*INDEX('Retention Calc'!$B$2:$Q$2698,0,MATCH($B30+G$26,'Retention Calc'!$B$1:$Q$1,0)))/$C30),"")} -> 0.24107143 | H30: {=IFERROR(IF($B30+H$26>2026,"",SUMPRODUCT(('Retention Calc'!$R$2:$R$2698=$B30)*INDEX('Retention Calc'!$B$2:$Q$2698,0,MATCH($B30+H$26,'Retention Calc'!$B$1:$Q$1,0)))/$C30),"")} -> 0.25 | I30: {=IFERROR(IF($B30+I$26>2026,"",SUMPRODUCT(('Retention Calc'!$R$2:$R$2698=$B30)*INDEX('Retention Calc'!$B$2:$Q$2698,0,MATCH($B30+I$26,'Retention Calc'!$B$1:$Q$1,0)))/$C30),"")} -> 0.20535714 | J30: {=IFERROR(IF($B30+J$26>2026,"",SUMPRODUCT(('Retention Calc'!$R$2:$R$2698=$B30)*INDEX('Retention Calc'!$B$2:$Q$2698,0,MATCH($B30+J$26,'Retention Calc'!$B$1:$Q$1,0)))/$C30),"")} -> 0.13392857 | K30: {=IFERROR(IF($B30+K$26>2026,"",SUMPRODUCT(('Retention Calc'!$R$2:$R$2698=$B30)*INDEX('Retention Calc'!$B$2:$Q$2698,0,MATCH($B30+K$26,'Retention Calc'!$B$1:$Q$1,0)))/$C30),"")} -> 0.16964286 | ... S30: {=IFERROR(IF($B30+S$26>2026,"",SUMPRODUCT(('Retention Calc'!$R$2:$R$2698=$B30)*INDEX('Retention Calc'!$B$2:$Q$2698,0,MATCH($B30+S$26,'Retention Calc'!$B$1:$Q$1,0)))/$C30),"")} | V30: ="Year "&3 -> Year 3 | W30: =IF(G27="",NA(),G27) -> 0.45697329 | X30: =IF(G28="",NA(),G28) -> 0.32317073 | Y30: =IF(G29="",NA(),G29) -> 0.27407407 | Z30: =IF(G30="",NA(),G30) -> 0.24107143 | AA30: =IF(G31="",NA(),G31) -> 0.22 | AB30: =IF(G32="",NA(),G32) -> 0.11046512 | AC30: =IF(G33="",NA(),G33) -> 0.1509434 | AD30: =IF(G34="",NA(),G34) -> 0.31451613 | AE30: =IF(G35="",NA(),G35) -> 0.11971831 | AF30: =IF(G36="",NA(),G36) -> 0.13580247 | AG30: =IF(G37="",NA(),G37) -> 0.18085106 | AH30: =IF(G38="",NA(),G38) -> 0.12637363 | AI30: =IF(G39="",NA(),G39) -> 0.16666667 | AJ30: =IF(G40="",NA(),G40) -> #N/A | AK30: =IF(G41="",NA(),G41) -> #N/A | AL30: =IF(G42="",NA(),G42) -> #N/A | AM30: =IF(G43="",NA(),G43) -> 0.23042705 | AN30: ="FY"&B30 -> FY2014
B31: =B30+1 -> 2015 | C31: =COUNTIF('Retention Calc'!$R$2:$R$2698,$B31) -> 150 | D31: {=IFERROR(IF($B31+D$26>2026,"",SUMPRODUCT(('Retention Calc'!$R$2:$R$2698=$B31)*INDEX('Retention Calc'!$B$2:$Q$2698,0,MATCH($B31+D$26,'Retention Calc'!$B$1:$Q$1,0)))/$C31),"")} -> 1 | E31: {=IFERROR(IF($B31+E$26>2026,"",SUMPRODUCT(('Retention Calc'!$R$2:$R$2698=$B31)*INDEX('Retention Calc'!$B$2:$Q$2698,0,MATCH($B31+E$26,'Retention Calc'!$B$1:$Q$1,0)))/$C31),"")} -> 0.27333333 | F31: {=IFERROR(IF($B31+F$26>2026,"",SUMPRODUCT(('Retention Calc'!$R$2:$R$2698=$B31)*INDEX('Retention Calc'!$B$2:$Q$2698,0,MATCH($B31+F$26,'Retention Calc'!$B$1:$Q$1,0)))/$C31),"")} -> 0.22666667 | G31: {=IFERROR(IF($B31+G$26>2026,"",SUMPRODUCT(('Retention Calc'!$R$2:$R$2698=$B31)*INDEX('Retention Calc'!$B$2:$Q$2698,0,MATCH($B31+G$26,'Retention Calc'!$B$1:$Q$1,0)))/$C31),"")} -> 0.22 | H31: {=IFERROR(IF($B31+H$26>2026,"",SUMPRODUCT(('Retention Calc'!$R$2:$R$2698=$B31)*INDEX('Retention Calc'!$B$2:$Q$2698,0,MATCH($B31+H$26,'Retention Calc'!$B$1:$Q$1,0)))/$C31),"")} -> 0.2 | I31: {=IFERROR(IF($B31+I$26>2026,"",SUMPRODUCT(('Retention Calc'!$R$2:$R$2698=$B31)*INDEX('Retention Calc'!$B$2:$Q$2698,0,MATCH($B31+I$26,'Retention Calc'!$B$1:$Q$1,0)))/$C31),"")} -> 0.16666667 | J31: {=IFERROR(IF($B31+J$26>2026,"",SUMPRODUCT(('Retention Calc'!$R$2:$R$2698=$B31)*INDEX('Retention Calc'!$B$2:$Q$2698,0,MATCH($B31+J$26,'Retention Calc'!$B$1:$Q$1,0)))/$C31),"")} -> 0.18 | K31: {=IFERROR(IF($B31+K$26>2026,"",SUMPRODUCT(('Retention Calc'!$R$2:$R$2698=$B31)*INDEX('Retention Calc'!$B$2:$Q$2698,0,MATCH($B31+K$26,'Retention Calc'!$B$1:$Q$1,0)))/$C31),"")} -> 0.14 | ... S31: {=IFERROR(IF($B31+S$26>2026,"",SUMPRODUCT(('Retention Calc'!$R$2:$R$2698=$B31)*INDEX('Retention Calc'!$B$2:$Q$2698,0,MATCH($B31+S$26,'Retention Calc'!$B$1:$Q$1,0)))/$C31),"")} | V31: ="Year "&4 -> Year 4 | W31: =IF(H27="",NA(),H27) -> 0.47477745 | X31: =IF(H28="",NA(),H28) -> 0.29268293 | Y31: =IF(H29="",NA(),H29) -> 0.27407407 | Z31: =IF(H30="",NA(),H30) -> 0.25 | AA31: =IF(H31="",NA(),H31) -> 0.2 | AB31: =IF(H32="",NA(),H32) -> 0.087209302 | AC31: =IF(H33="",NA(),H33) -> 0.16037736 | AD31: =IF(H34="",NA(),H34) -> 0.23387097 | AE31: =IF(H35="",NA(),H35) -> 0.098591549 | AF31: =IF(H36="",NA(),H36) -> 0.14814815 | AG31: =IF(H37="",NA(),H37) -> 0.20744681 | AH31: =IF(H38="",NA(),H38) -> 0.14285714 | AI31: =IF(H39="",NA(),H39) -> #N/A | AJ31: =IF(H40="",NA(),H40) -> #N/A | AK31: =IF(H41="",NA(),H41) -> #N/A | AL31: =IF(H42="",NA(),H42) -> #N/A | AM31: =IF(H43="",NA(),H43) -> 0.23269231 | AN31: ="FY"&B31 -> FY2015
B32: =B31+1 -> 2016 | C32: =COUNTIF('Retention Calc'!$R$2:$R$2698,$B32) -> 172 | D32: {=IFERROR(IF($B32+D$26>2026,"",SUMPRODUCT(('Retention Calc'!$R$2:$R$2698=$B32)*INDEX('Retention Calc'!$B$2:$Q$2698,0,MATCH($B32+D$26,'Retention Calc'!$B$1:$Q$1,0)))/$C32),"")} -> 1 | E32: {=IFERROR(IF($B32+E$26>2026,"",SUMPRODUCT(('Retention Calc'!$R$2:$R$2698=$B32)*INDEX('Retention Calc'!$B$2:$Q$2698,0,MATCH($B32+E$26,'Retention Calc'!$B$1:$Q$1,0)))/$C32),"")} -> 0.18023256 | F32: {=IFERROR(IF($B32+F$26>2026,"",SUMPRODUCT(('Retention Calc'!$R$2:$R$2698=$B32)*INDEX('Retention Calc'!$B$2:$Q$2698,0,MATCH($B32+F$26,'Retention Calc'!$B$1:$Q$1,0)))/$C32),"")} -> 0.15116279 | G32: {=IFERROR(IF($B32+G$26>2026,"",SUMPRODUCT(('Retention Calc'!$R$2:$R$2698=$B32)*INDEX('Retention Calc'!$B$2:$Q$2698,0,MATCH($B32+G$26,'Retention Calc'!$B$1:$Q$1,0)))/$C32),"")} -> 0.11046512 | H32: {=IFERROR(IF($B32+H$26>2026,"",SUMPRODUCT(('Retention Calc'!$R$2:$R$2698=$B32)*INDEX('Retention Calc'!$B$2:$Q$2698,0,MATCH($B32+H$26,'Retention Calc'!$B$1:$Q$1,0)))/$C32),"")} -> 0.087209302 | I32: {=IFERROR(IF($B32+I$26>2026,"",SUMPRODUCT(('Retention Calc'!$R$2:$R$2698=$B32)*INDEX('Retention Calc'!$B$2:$Q$2698,0,MATCH($B32+I$26,'Retention Calc'!$B$1:$Q$1,0)))/$C32),"")} -> 0.11627907 | J32: {=IFERROR(IF($B32+J$26>2026,"",SUMPRODUCT(('Retention Calc'!$R$2:$R$2698=$B32)*INDEX('Retention Calc'!$B$2:$Q$2698,0,MATCH($B32+J$26,'Retention Calc'!$B$1:$Q$1,0)))/$C32),"")} -> 0.11046512 | K32: {=IFERROR(IF($B32+K$26>2026,"",SUMPRODUCT(('Retention Calc'!$R$2:$R$2698=$B32)*INDEX('Retention Calc'!$B$2:$Q$2698,0,MATCH($B32+K$26,'Retention Calc'!$B$1:$Q$1,0)))/$C32),"")} -> 0.075581395 | ... S32: {=IFERROR(IF($B32+S$26>2026,"",SUMPRODUCT(('Retention Calc'!$R$2:$R$2698=$B32)*INDEX('Retention Calc'!$B$2:$Q$2698,0,MATCH($B32+S$26,'Retention Calc'!$B$1:$Q$1,0)))/$C32),"")} | V32: ="Year "&5 -> Year 5 | W32: =IF(I27="",NA(),I27) -> 0.44807122 | X32: =IF(I28="",NA(),I28) -> 0.2804878 | Y32: =IF(I29="",NA(),I29) -> 0.23703704 | Z32: =IF(I30="",NA(),I30) -> 0.20535714 | AA32: =IF(I31="",NA(),I31) -> 0.16666667 | AB32: =IF(I32="",NA(),I32) -> 0.11627907 | AC32: =IF(I33="",NA(),I33) -> 0.11320755 | AD32: =IF(I34="",NA(),I34) -> 0.20967742 | AE32: =IF(I35="",NA(),I35) -> 0.11267606 | AF32: =IF(I36="",NA(),I36) -> 0.14814815 | AG32: =IF(I37="",NA(),I37) -> 0.13829787 | AH32: =IF(I38="",NA(),I38) -> #N/A | AI32: =IF(I39="",NA(),I39) -> #N/A | AJ32: =IF(I40="",NA(),I40) -> #N/A | AK32: =IF(I41="",NA(),I41) -> #N/A | AL32: =IF(I42="",NA(),I42) -> #N/A | AM32: =IF(I43="",NA(),I43) -> 0.21759747 | AN32: ="FY"&B32 -> FY2016
B33: =B32+1 -> 2017 | C33: =COUNTIF('Retention Calc'!$R$2:$R$2698,$B33) -> 212 | D33: {=IFERROR(IF($B33+D$26>2026,"",SUMPRODUCT(('Retention Calc'!$R$2:$R$2698=$B33)*INDEX('Retention Calc'!$B$2:$Q$2698,0,MATCH($B33+D$26,'Retention Calc'!$B$1:$Q$1,0)))/$C33),"")} -> 1 | E33: {=IFERROR(IF($B33+E$26>2026,"",SUMPRODUCT(('Retention Calc'!$R$2:$R$2698=$B33)*INDEX('Retention Calc'!$B$2:$Q$2698,0,MATCH($B33+E$26,'Retention Calc'!$B$1:$Q$1,0)))/$C33),"")} -> 0.20754717 | F33: {=IFERROR(IF($B33+F$26>2026,"",SUMPRODUCT(('Retention Calc'!$R$2:$R$2698=$B33)*INDEX('Retention Calc'!$B$2:$Q$2698,0,MATCH($B33+F$26,'Retention Calc'!$B$1:$Q$1,0)))/$C33),"")} -> 0.13679245 | G33: {=IFERROR(IF($B33+G$26>2026,"",SUMPRODUCT(('Retention Calc'!$R$2:$R$2698=$B33)*INDEX('Retention Calc'!$B$2:$Q$2698,0,MATCH($B33+G$26,'Retention Calc'!$B$1:$Q$1,0)))/$C33),"")} -> 0.1509434 | H33: {=IFERROR(IF($B33+H$26>2026,"",SUMPRODUCT(('Retention Calc'!$R$2:$R$2698=$B33)*INDEX('Retention Calc'!$B$2:$Q$2698,0,MATCH($B33+H$26,'Retention Calc'!$B$1:$Q$1,0)))/$C33),"")} -> 0.16037736 | I33: {=IFERROR(IF($B33+I$26>2026,"",SUMPRODUCT(('Retention Calc'!$R$2:$R$2698=$B33)*INDEX('Retention Calc'!$B$2:$Q$2698,0,MATCH($B33+I$26,'Retention Calc'!$B$1:$Q$1,0)))/$C33),"")} -> 0.11320755 | J33: {=IFERROR(IF($B33+J$26>2026,"",SUMPRODUCT(('Retention Calc'!$R$2:$R$2698=$B33)*INDEX('Retention Calc'!$B$2:$Q$2698,0,MATCH($B33+J$26,'Retention Calc'!$B$1:$Q$1,0)))/$C33),"")} -> 0.094339623 | K33: {=IFERROR(IF($B33+K$26>2026,"",SUMPRODUCT(('Retention Calc'!$R$2:$R$2698=$B33)*INDEX('Retention Calc'!$B$2:$Q$2698,0,MATCH($B33+K$26,'Retention Calc'!$B$1:$Q$1,0)))/$C33),"")} -> 0.11320755 | ... S33: {=IFERROR(IF($B33+S$26>2026,"",SUMPRODUCT(('Retention Calc'!$R$2:$R$2698=$B33)*INDEX('Retention Calc'!$B$2:$Q$2698,0,MATCH($B33+S$26,'Retention Calc'!$B$1:$Q$1,0)))/$C33),"")} | V33: ="Year "&6 -> Year 6 | W33: =IF(J27="",NA(),J27) -> 0.39762611 | X33: =IF(J28="",NA(),J28) -> 0.24390244 | Y33: =IF(J29="",NA(),J29) -> 0.17777778 | Z33: =IF(J30="",NA(),J30) -> 0.13392857 | AA33: =IF(J31="",NA(),J31) -> 0.18 | AB33: =IF(J32="",NA(),J32) -> 0.11046512 | AC33: =IF(J33="",NA(),J33) -> 0.094339623 | AD33: =IF(J34="",NA(),J34) -> 0.20967742 | AE33: =IF(J35="",NA(),J35) -> 0.11971831 | AF33: =IF(J36="",NA(),J36) -> 0.11111111 | AG33: =IF(J37="",NA(),J37) -> #N/A | AH33: =IF(J38="",NA(),J38) -> #N/A | AI33: =IF(J39="",NA(),J39) -> #N/A | AJ33: =IF(J40="",NA(),J40) -> #N/A | AK33: =IF(J41="",NA(),J41) -> #N/A | AL33: =IF(J42="",NA(),J42) -> #N/A | AM33: =IF(J43="",NA(),J43) -> 0.19883041 | AN33: ="FY"&B33 -> FY2017
B34: =B33+1 -> 2018 | C34: =COUNTIF('Retention Calc'!$R$2:$R$2698,$B34) -> 124 | D34: {=IFERROR(IF($B34+D$26>2026,"",SUMPRODUCT(('Retention Calc'!$R$2:$R$2698=$B34)*INDEX('Retention Calc'!$B$2:$Q$2698,0,MATCH($B34+D$26,'Retention Calc'!$B$1:$Q$1,0)))/$C34),"")} -> 1 | E34: {=IFERROR(IF($B34+E$26>2026,"",SUMPRODUCT(('Retention Calc'!$R$2:$R$2698=$B34)*INDEX('Retention Calc'!$B$2:$Q$2698,0,MATCH($B34+E$26,'Retention Calc'!$B$1:$Q$1,0)))/$C34),"")} -> 0.21774194 | F34: {=IFERROR(IF($B34+F$26>2026,"",SUMPRODUCT(('Retention Calc'!$R$2:$R$2698=$B34)*INDEX('Retention Calc'!$B$2:$Q$2698,0,MATCH($B34+F$26,'Retention Calc'!$B$1:$Q$1,0)))/$C34),"")} -> 0.22580645 | G34: {=IFERROR(IF($B34+G$26>2026,"",SUMPRODUCT(('Retention Calc'!$R$2:$R$2698=$B34)*INDEX('Retention Calc'!$B$2:$Q$2698,0,MATCH($B34+G$26,'Retention Calc'!$B$1:$Q$1,0)))/$C34),"")} -> 0.31451613 | H34: {=IFERROR(IF($B34+H$26>2026,"",SUMPRODUCT(('Retention Calc'!$R$2:$R$2698=$B34)*INDEX('Retention Calc'!$B$2:$Q$2698,0,MATCH($B34+H$26,'Retention Calc'!$B$1:$Q$1,0)))/$C34),"")} -> 0.23387097 | I34: {=IFERROR(IF($B34+I$26>2026,"",SUMPRODUCT(('Retention Calc'!$R$2:$R$2698=$B34)*INDEX('Retention Calc'!$B$2:$Q$2698,0,MATCH($B34+I$26,'Retention Calc'!$B$1:$Q$1,0)))/$C34),"")} -> 0.20967742 | J34: {=IFERROR(IF($B34+J$26>2026,"",SUMPRODUCT(('Retention Calc'!$R$2:$R$2698=$B34)*INDEX('Retention Calc'!$B$2:$Q$2698,0,MATCH($B34+J$26,'Retention Calc'!$B$1:$Q$1,0)))/$C34),"")} -> 0.20967742 | K34: {=IFERROR(IF($B34+K$26>2026,"",SUMPRODUCT(('Retention Calc'!$R$2:$R$2698=$B34)*INDEX('Retention Calc'!$B$2:$Q$2698,0,MATCH($B34+K$26,'Retention Calc'!$B$1:$Q$1,0)))/$C34),"")} -> 0.17741935 | ... S34: {=IFERROR(IF($B34+S$26>2026,"",SUMPRODUCT(('Retention Calc'!$R$2:$R$2698=$B34)*INDEX('Retention Calc'!$B$2:$Q$2698,0,MATCH($B34+S$26,'Retention Calc'!$B$1:$Q$1,0)))/$C34),"")} | V34: ="Year "&7 -> Year 7 | W34: =IF(K27="",NA(),K27) -> 0.38278932 | X34: =IF(K28="",NA(),K28) -> 0.20121951 | Y34: =IF(K29="",NA(),K29) -> 0.15555556 | Z34: =IF(K30="",NA(),K30) -> 0.16964286 | AA34: =IF(K31="",NA(),K31) -> 0.14 | AB34: =IF(K32="",NA(),K32) -> 0.075581395 | AC34: =IF(K33="",NA(),K33) -> 0.11320755 | AD34: =IF(K34="",NA(),K34) -> 0.17741935 | AE34: =IF(K35="",NA(),K35) -> 0.091549296 | AF34: =IF(K36="",NA(),K36) -> #N/A | AG34: =IF(K37="",NA(),K37) -> #N/A | AH34: =IF(K38="",NA(),K38) -> #N/A | AI34: =IF(K39="",NA(),K39) -> #N/A | AJ34: =IF(K40="",NA(),K40) -> #N/A | AK34: =IF(K41="",NA(),K41) -> #N/A | AL34: =IF(K42="",NA(),K42) -> #N/A | AM34: =IF(K43="",NA(),K43) -> 0.19056848 | AN34: ="FY"&B34 -> FY2018
B35: =B34+1 -> 2019 | C35: =COUNTIF('Retention Calc'!$R$2:$R$2698,$B35) -> 142 | D35: {=IFERROR(IF($B35+D$26>2026,"",SUMPRODUCT(('Retention Calc'!$R$2:$R$2698=$B35)*INDEX('Retention Calc'!$B$2:$Q$2698,0,MATCH($B35+D$26,'Retention Calc'!$B$1:$Q$1,0)))/$C35),"")} -> 1 | E35: {=IFERROR(IF($B35+E$26>2026,"",SUMPRODUCT(('Retention Calc'!$R$2:$R$2698=$B35)*INDEX('Retention Calc'!$B$2:$Q$2698,0,MATCH($B35+E$26,'Retention Calc'!$B$1:$Q$1,0)))/$C35),"")} -> 0.084507042 | F35: {=IFERROR(IF($B35+F$26>2026,"",SUMPRODUCT(('Retention Calc'!$R$2:$R$2698=$B35)*INDEX('Retention Calc'!$B$2:$Q$2698,0,MATCH($B35+F$26,'Retention Calc'!$B$1:$Q$1,0)))/$C35),"")} -> 0.13380282 | G35: {=IFERROR(IF($B35+G$26>2026,"",SUMPRODUCT(('Retention Calc'!$R$2:$R$2698=$B35)*INDEX('Retention Calc'!$B$2:$Q$2698,0,MATCH($B35+G$26,'Retention Calc'!$B$1:$Q$1,0)))/$C35),"")} -> 0.11971831 | H35: {=IFERROR(IF($B35+H$26>2026,"",SUMPRODUCT(('Retention Calc'!$R$2:$R$2698=$B35)*INDEX('Retention Calc'!$B$2:$Q$2698,0,MATCH($B35+H$26,'Retention Calc'!$B$1:$Q$1,0)))/$C35),"")} -> 0.098591549 | I35: {=IFERROR(IF($B35+I$26>2026,"",SUMPRODUCT(('Retention Calc'!$R$2:$R$2698=$B35)*INDEX('Retention Calc'!$B$2:$Q$2698,0,MATCH($B35+I$26,'Retention Calc'!$B$1:$Q$1,0)))/$C35),"")} -> 0.11267606 | J35: {=IFERROR(IF($B35+J$26>2026,"",SUMPRODUCT(('Retention Calc'!$R$2:$R$2698=$B35)*INDEX('Retention Calc'!$B$2:$Q$2698,0,MATCH($B35+J$26,'Retention Calc'!$B$1:$Q$1,0)))/$C35),"")} -> 0.11971831 | K35: {=IFERROR(IF($B35+K$26>2026,"",SUMPRODUCT(('Retention Calc'!$R$2:$R$2698=$B35)*INDEX('Retention Calc'!$B$2:$Q$2698,0,MATCH($B35+K$26,'Retention Calc'!$B$1:$Q$1,0)))/$C35),"")} -> 0.091549296 | ... S35: {=IFERROR(IF($B35+S$26>2026,"",SUMPRODUCT(('Retention Calc'!$R$2:$R$2698=$B35)*INDEX('Retention Calc'!$B$2:$Q$2698,0,MATCH($B35+S$26,'Retention Calc'!$B$1:$Q$1,0)))/$C35),"")} | V35: ="Year "&8 -> Year 8 | W35: =IF(L27="",NA(),L27) -> 0.33234421 | X35: =IF(L28="",NA(),L28) -> 0.19512195 | Y35: =IF(L29="",NA(),L29) -> 0.17037037 | Z35: =IF(L30="",NA(),L30) -> 0.125 | AA35: =IF(L31="",NA(),L31) -> 0.15333333 | AB35: =IF(L32="",NA(),L32) -> 0.075581395 | AC35: =IF(L33="",NA(),L33) -> 0.11320755 | AD35: =IF(L34="",NA(),L34) -> 0.2016129 | AE35: =IF(L35="",NA(),L35) -> #N/A | AF35: =IF(L36="",NA(),L36) -> #N/A | AG35: =IF(L37="",NA(),L37) -> #N/A | AH35: =IF(L38="",NA(),L38) -> #N/A | AI35: =IF(L39="",NA(),L39) -> #N/A | AJ35: =IF(L40="",NA(),L40) -> #N/A | AK35: =IF(L41="",NA(),L41) -> #N/A | AL35: =IF(L42="",NA(),L42) -> #N/A | AM35: =IF(L43="",NA(),L43) -> 0.18918919 | AN35: ="FY"&B35 -> FY2019
B36: =B35+1 -> 2020 | C36: =COUNTIF('Retention Calc'!$R$2:$R$2698,$B36) -> 162 | D36: {=IFERROR(IF($B36+D$26>2026,"",SUMPRODUCT(('Retention Calc'!$R$2:$R$2698=$B36)*INDEX('Retention Calc'!$B$2:$Q$2698,0,MATCH($B36+D$26,'Retention Calc'!$B$1:$Q$1,0)))/$C36),"")} -> 1 | E36: {=IFERROR(IF($B36+E$26>2026,"",SUMPRODUCT(('Retention Calc'!$R$2:$R$2698=$B36)*INDEX('Retention Calc'!$B$2:$Q$2698,0,MATCH($B36+E$26,'Retention Calc'!$B$1:$Q$1,0)))/$C36),"")} -> 0.24691358 | F36: {=IFERROR(IF($B36+F$26>2026,"",SUMPRODUCT(('Retention Calc'!$R$2:$R$2698=$B36)*INDEX('Retention Calc'!$B$2:$Q$2698,0,MATCH($B36+F$26,'Retention Calc'!$B$1:$Q$1,0)))/$C36),"")} -> 0.17283951 | G36: {=IFERROR(IF($B36+G$26>2026,"",SUMPRODUCT(('Retention Calc'!$R$2:$R$2698=$B36)*INDEX('Retention Calc'!$B$2:$Q$2698,0,MATCH($B36+G$26,'Retention Calc'!$B$1:$Q$1,0)))/$C36),"")} -> 0.13580247 | H36: {=IFERROR(IF($B36+H$26>2026,"",SUMPRODUCT(('Retention Calc'!$R$2:$R$2698=$B36)*INDEX('Retention Calc'!$B$2:$Q$2698,0,MATCH($B36+H$26,'Retention Calc'!$B$1:$Q$1,0)))/$C36),"")} -> 0.14814815 | I36: {=IFERROR(IF($B36+I$26>2026,"",SUMPRODUCT(('Retention Calc'!$R$2:$R$2698=$B36)*INDEX('Retention Calc'!$B$2:$Q$2698,0,MATCH($B36+I$26,'Retention Calc'!$B$1:$Q$1,0)))/$C36),"")} -> 0.14814815 | J36: {=IFERROR(IF($B36+J$26>2026,"",SUMPRODUCT(('Retention Calc'!$R$2:$R$2698=$B36)*INDEX('Retention Calc'!$B$2:$Q$2698,0,MATCH($B36+J$26,'Retention Calc'!$B$1:$Q$1,0)))/$C36),"")} -> 0.11111111 | K36: {=IFERROR(IF($B36+K$26>2026,"",SUMPRODUCT(('Retention Calc'!$R$2:$R$2698=$B36)*INDEX('Retention Calc'!$B$2:$Q$2698,0,MATCH($B36+K$26,'Retention Calc'!$B$1:$Q$1,0)))/$C36),"")} | ... S36: {=IFERROR(IF($B36+S$26>2026,"",SUMPRODUCT(('Retention Calc'!$R$2:$R$2698=$B36)*INDEX('Retention Calc'!$B$2:$Q$2698,0,MATCH($B36+S$26,'Retention Calc'!$B$1:$Q$1,0)))/$C36),"")} | V36: ="Year "&9 -> Year 9 | W36: =IF(M27="",NA(),M27) -> 0.3620178 | X36: =IF(M28="",NA(),M28) -> 0.19512195 | Y36: =IF(M29="",NA(),M29) -> 0.11111111 | Z36: =IF(M30="",NA(),M30) -> 0.15178571 | AA36: =IF(M31="",NA(),M31) -> 0.14 | AB36: =IF(M32="",NA(),M32) -> 0.063953488 | AC36: =IF(M33="",NA(),M33) -> 0.10849057 | AD36: =IF(M34="",NA(),M34) -> #N/A | AE36: =IF(M35="",NA(),M35) -> #N/A | AF36: =IF(M36="",NA(),M36) -> #N/A | AG36: =IF(M37="",NA(),M37) -> #N/A | AH36: =IF(M38="",NA(),M38) -> #N/A | AI36: =IF(M39="",NA(),M39) -> #N/A | AJ36: =IF(M40="",NA(),M40) -> #N/A | AK36: =IF(M41="",NA(),M41) -> #N/A | AL36: =IF(M42="",NA(),M42) -> #N/A | AM36: =IF(M43="",NA(),M43) -> 0.18798752 | AN36: ="FY"&B36 -> FY2020
B37: =B36+1 -> 2021 | C37: =COUNTIF('Retention Calc'!$R$2:$R$2698,$B37) -> 188 | D37: {=IFERROR(IF($B37+D$26>2026,"",SUMPRODUCT(('Retention Calc'!$R$2:$R$2698=$B37)*INDEX('Retention Calc'!$B$2:$Q$2698,0,MATCH($B37+D$26,'Retention Calc'!$B$1:$Q$1,0)))/$C37),"")} -> 1 | E37: {=IFERROR(IF($B37+E$26>2026,"",SUMPRODUCT(('Retention Calc'!$R$2:$R$2698=$B37)*INDEX('Retention Calc'!$B$2:$Q$2698,0,MATCH($B37+E$26,'Retention Calc'!$B$1:$Q$1,0)))/$C37),"")} -> 0.21808511 | F37: {=IFERROR(IF($B37+F$26>2026,"",SUMPRODUCT(('Retention Calc'!$R$2:$R$2698=$B37)*INDEX('Retention Calc'!$B$2:$Q$2698,0,MATCH($B37+F$26,'Retention Calc'!$B$1:$Q$1,0)))/$C37),"")} -> 0.20212766 | G37: {=IFERROR(IF($B37+G$26>2026,"",SUMPRODUCT(('Retention Calc'!$R$2:$R$2698=$B37)*INDEX('Retention Calc'!$B$2:$Q$2698,0,MATCH($B37+G$26,'Retention Calc'!$B$1:$Q$1,0)))/$C37),"")} -> 0.18085106 | H37: {=IFERROR(IF($B37+H$26>2026,"",SUMPRODUCT(('Retention Calc'!$R$2:$R$2698=$B37)*INDEX('Retention Calc'!$B$2:$Q$2698,0,MATCH($B37+H$26,'Retention Calc'!$B$1:$Q$1,0)))/$C37),"")} -> 0.20744681 | I37: {=IFERROR(IF($B37+I$26>2026,"",SUMPRODUCT(('Retention Calc'!$R$2:$R$2698=$B37)*INDEX('Retention Calc'!$B$2:$Q$2698,0,MATCH($B37+I$26,'Retention Calc'!$B$1:$Q$1,0)))/$C37),"")} -> 0.13829787 | J37: {=IFERROR(IF($B37+J$26>2026,"",SUMPRODUCT(('Retention Calc'!$R$2:$R$2698=$B37)*INDEX('Retention Calc'!$B$2:$Q$2698,0,MATCH($B37+J$26,'Retention Calc'!$B$1:$Q$1,0)))/$C37),"")} | K37: {=IFERROR(IF($B37+K$26>2026,"",SUMPRODUCT(('Retention Calc'!$R$2:$R$2698=$B37)*INDEX('Retention Calc'!$B$2:$Q$2698,0,MATCH($B37+K$26,'Retention Calc'!$B$1:$Q$1,0)))/$C37),"")} | ... S37: {=IFERROR(IF($B37+S$26>2026,"",SUMPRODUCT(('Retention Calc'!$R$2:$R$2698=$B37)*INDEX('Retention Calc'!$B$2:$Q$2698,0,MATCH($B37+S$26,'Retention Calc'!$B$1:$Q$1,0)))/$C37),"")} | V37: ="Year "&10 -> Year 10 | W37: =IF(N27="",NA(),N27) -> 0.3115727 | X37: =IF(N28="",NA(),N28) -> 0.19512195 | Y37: =IF(N29="",NA(),N29) -> 0.13333333 | Z37: =IF(N30="",NA(),N30) -> 0.089285714 | AA37: =IF(N31="",NA(),N31) -> 0.12 | AB37: =IF(N32="",NA(),N32) -> 0.069767442 | AC37: =IF(N33="",NA(),N33) -> #N/A | AD37: =IF(N34="",NA(),N34) -> #N/A | AE37: =IF(N35="",NA(),N35) -> #N/A | AF37: =IF(N36="",NA(),N36) -> #N/A | AG37: =IF(N37="",NA(),N37) -> #N/A | AH37: =IF(N38="",NA(),N38) -> #N/A | AI37: =IF(N39="",NA(),N39) -> #N/A | AJ37: =IF(N40="",NA(),N40) -> #N/A | AK37: =IF(N41="",NA(),N41) -> #N/A | AL37: =IF(N42="",NA(),N42) -> #N/A | AM37: =IF(N43="",NA(),N43) -> 0.18224299 | AN37: ="FY"&B37 -> FY2021
B38: =B37+1 -> 2022 | C38: =COUNTIF('Retention Calc'!$R$2:$R$2698,$B38) -> 182 | D38: {=IFERROR(IF($B38+D$26>2026,"",SUMPRODUCT(('Retention Calc'!$R$2:$R$2698=$B38)*INDEX('Retention Calc'!$B$2:$Q$2698,0,MATCH($B38+D$26,'Retention Calc'!$B$1:$Q$1,0)))/$C38),"")} -> 1 | E38: {=IFERROR(IF($B38+E$26>2026,"",SUMPRODUCT(('Retention Calc'!$R$2:$R$2698=$B38)*INDEX('Retention Calc'!$B$2:$Q$2698,0,MATCH($B38+E$26,'Retention Calc'!$B$1:$Q$1,0)))/$C38),"")} -> 0.31318681 | F38: {=IFERROR(IF($B38+F$26>2026,"",SUMPRODUCT(('Retention Calc'!$R$2:$R$2698=$B38)*INDEX('Retention Calc'!$B$2:$Q$2698,0,MATCH($B38+F$26,'Retention Calc'!$B$1:$Q$1,0)))/$C38),"")} -> 0.1978022 | G38: {=IFERROR(IF($B38+G$26>2026,"",SUMPRODUCT(('Retention Calc'!$R$2:$R$2698=$B38)*INDEX('Retention Calc'!$B$2:$Q$2698,0,MATCH($B38+G$26,'Retention Calc'!$B$1:$Q$1,0)))/$C38),"")} -> 0.12637363 | H38: {=IFERROR(IF($B38+H$26>2026,"",SUMPRODUCT(('Retention Calc'!$R$2:$R$2698=$B38)*INDEX('Retention Calc'!$B$2:$Q$2698,0,MATCH($B38+H$26,'Retention Calc'!$B$1:$Q$1,0)))/$C38),"")} -> 0.14285714 | I38: {=IFERROR(IF($B38+I$26>2026,"",SUMPRODUCT(('Retention Calc'!$R$2:$R$2698=$B38)*INDEX('Retention Calc'!$B$2:$Q$2698,0,MATCH($B38+I$26,'Retention Calc'!$B$1:$Q$1,0)))/$C38),"")} | J38: {=IFERROR(IF($B38+J$26>2026,"",SUMPRODUCT(('Retention Calc'!$R$2:$R$2698=$B38)*INDEX('Retention Calc'!$B$2:$Q$2698,0,MATCH($B38+J$26,'Retention Calc'!$B$1:$Q$1,0)))/$C38),"")} | K38: {=IFERROR(IF($B38+K$26>2026,"",SUMPRODUCT(('Retention Calc'!$R$2:$R$2698=$B38)*INDEX('Retention Calc'!$B$2:$Q$2698,0,MATCH($B38+K$26,'Retention Calc'!$B$1:$Q$1,0)))/$C38),"")} | ... S38: {=IFERROR(IF($B38+S$26>2026,"",SUMPRODUCT(('Retention Calc'!$R$2:$R$2698=$B38)*INDEX('Retention Calc'!$B$2:$Q$2698,0,MATCH($B38+S$26,'Retention Calc'!$B$1:$Q$1,0)))/$C38),"")} | V38: ="Year "&11 -> Year 11 | W38: =IF(O27="",NA(),O27) -> 0.30563798 | X38: =IF(O28="",NA(),O28) -> 0.19512195 | Y38: =IF(O29="",NA(),O29) -> 0.1037037 | Z38: =IF(O30="",NA(),O30) -> 0.089285714 | AA38: =IF(O31="",NA(),O31) -> 0.12 | AB38: =IF(O32="",NA(),O32) -> #N/A | AC38: =IF(O33="",NA(),O33) -> #N/A | AD38: =IF(O34="",NA(),O34) -> #N/A | AE38: =IF(O35="",NA(),O35) -> #N/A | AF38: =IF(O36="",NA(),O36) -> #N/A | AG38: =IF(O37="",NA(),O37) -> #N/A | AH38: =IF(O38="",NA(),O38) -> #N/A | AI38: =IF(O39="",NA(),O39) -> #N/A | AJ38: =IF(O40="",NA(),O40) -> #N/A | AK38: =IF(O41="",NA(),O41) -> #N/A | AL38: =IF(O42="",NA(),O42) -> #N/A | AM38: =IF(O43="",NA(),O43) -> 0.19710468 | AN38: ="FY"&B38 -> FY2022
B39: =B38+1 -> 2023 | C39: =COUNTIF('Retention Calc'!$R$2:$R$2698,$B39) -> 168 | D39: {=IFERROR(IF($B39+D$26>2026,"",SUMPRODUCT(('Retention Calc'!$R$2:$R$2698=$B39)*INDEX('Retention Calc'!$B$2:$Q$2698,0,MATCH($B39+D$26,'Retention Calc'!$B$1:$Q$1,0)))/$C39),"")} -> 1 | E39: {=IFERROR(IF($B39+E$26>2026,"",SUMPRODUCT(('Retention Calc'!$R$2:$R$2698=$B39)*INDEX('Retention Calc'!$B$2:$Q$2698,0,MATCH($B39+E$26,'Retention Calc'!$B$1:$Q$1,0)))/$C39),"")} -> 0.28571429 | F39: {=IFERROR(IF($B39+F$26>2026,"",SUMPRODUCT(('Retention Calc'!$R$2:$R$2698=$B39)*INDEX('Retention Calc'!$B$2:$Q$2698,0,MATCH($B39+F$26,'Retention Calc'!$B$1:$Q$1,0)))/$C39),"")} -> 0.18452381 | G39: {=IFERROR(IF($B39+G$26>2026,"",SUMPRODUCT(('Retention Calc'!$R$2:$R$2698=$B39)*INDEX('Retention Calc'!$B$2:$Q$2698,0,MATCH($B39+G$26,'Retention Calc'!$B$1:$Q$1,0)))/$C39),"")} -> 0.16666667 | H39: {=IFERROR(IF($B39+H$26>2026,"",SUMPRODUCT(('Retention Calc'!$R$2:$R$2698=$B39)*INDEX('Retention Calc'!$B$2:$Q$2698,0,MATCH($B39+H$26,'Retention Calc'!$B$1:$Q$1,0)))/$C39),"")} | I39: {=IFERROR(IF($B39+I$26>2026,"",SUMPRODUCT(('Retention Calc'!$R$2:$R$2698=$B39)*INDEX('Retention Calc'!$B$2:$Q$2698,0,MATCH($B39+I$26,'Retention Calc'!$B$1:$Q$1,0)))/$C39),"")} | J39: {=IFERROR(IF($B39+J$26>2026,"",SUMPRODUCT(('Retention Calc'!$R$2:$R$2698=$B39)*INDEX('Retention Calc'!$B$2:$Q$2698,0,MATCH($B39+J$26,'Retention Calc'!$B$1:$Q$1,0)))/$C39),"")} | K39: {=IFERROR(IF($B39+K$26>2026,"",SUMPRODUCT(('Retention Calc'!$R$2:$R$2698=$B39)*INDEX('Retention Calc'!$B$2:$Q$2698,0,MATCH($B39+K$26,'Retention Calc'!$B$1:$Q$1,0)))/$C39),"")} | ... S39: {=IFERROR(IF($B39+S$26>2026,"",SUMPRODUCT(('Retention Calc'!$R$2:$R$2698=$B39)*INDEX('Retention Calc'!$B$2:$Q$2698,0,MATCH($B39+S$26,'Retention Calc'!$B$1:$Q$1,0)))/$C39),"")} | V39: ="Year "&12 -> Year 12 | W39: =IF(P27="",NA(),P27) -> 0.26409496 | X39: =IF(P28="",NA(),P28) -> 0.18902439 | Y39: =IF(P29="",NA(),P29) -> 0.11851852 | Z39: =IF(P30="",NA(),P30) -> 0.10714286 | AA39: =IF(P31="",NA(),P31) -> #N/A | AB39: =IF(P32="",NA(),P32) -> #N/A | AC39: =IF(P33="",NA(),P33) -> #N/A | AD39: =IF(P34="",NA(),P34) -> #N/A | AE39: =IF(P35="",NA(),P35) -> #N/A | AF39: =IF(P36="",NA(),P36) -> #N/A | AG39: =IF(P37="",NA(),P37) -> #N/A | AH39: =IF(P38="",NA(),P38) -> #N/A | AI39: =IF(P39="",NA(),P39) -> #N/A | AJ39: =IF(P40="",NA(),P40) -> #N/A | AK39: =IF(P41="",NA(),P41) -> #N/A | AL39: =IF(P42="",NA(),P42) -> #N/A | AM39: =IF(P43="",NA(),P43) -> 0.19786096 | AN39: ="FY"&B39 -> FY2023
B40: =B39+1 -> 2024 | C40: =COUNTIF('Retention Calc'!$R$2:$R$2698,$B40) -> 123 | D40: {=IFERROR(IF($B40+D$26>2026,"",SUMPRODUCT(('Retention Calc'!$R$2:$R$2698=$B40)*INDEX('Retention Calc'!$B$2:$Q$2698,0,MATCH($B40+D$26,'Retention Calc'!$B$1:$Q$1,0)))/$C40),"")} -> 1 | E40: {=IFERROR(IF($B40+E$26>2026,"",SUMPRODUCT(('Retention Calc'!$R$2:$R$2698=$B40)*INDEX('Retention Calc'!$B$2:$Q$2698,0,MATCH($B40+E$26,'Retention Calc'!$B$1:$Q$1,0)))/$C40),"")} -> 0.30081301 | F40: {=IFERROR(IF($B40+F$26>2026,"",SUMPRODUCT(('Retention Calc'!$R$2:$R$2698=$B40)*INDEX('Retention Calc'!$B$2:$Q$2698,0,MATCH($B40+F$26,'Retention Calc'!$B$1:$Q$1,0)))/$C40),"")} -> 0.2601626 | G40: {=IFERROR(IF($B40+G$26>2026,"",SUMPRODUCT(('Retention Calc'!$R$2:$R$2698=$B40)*INDEX('Retention Calc'!$B$2:$Q$2698,0,MATCH($B40+G$26,'Retention Calc'!$B$1:$Q$1,0)))/$C40),"")} | H40: {=IFERROR(IF($B40+H$26>2026,"",SUMPRODUCT(('Retention Calc'!$R$2:$R$2698=$B40)*INDEX('Retention Calc'!$B$2:$Q$2698,0,MATCH($B40+H$26,'Retention Calc'!$B$1:$Q$1,0)))/$C40),"")} | I40: {=IFERROR(IF($B40+I$26>2026,"",SUMPRODUCT(('Retention Calc'!$R$2:$R$2698=$B40)*INDEX('Retention Calc'!$B$2:$Q$2698,0,MATCH($B40+I$26,'Retention Calc'!$B$1:$Q$1,0)))/$C40),"")} | J40: {=IFERROR(IF($B40+J$26>2026,"",SUMPRODUCT(('Retention Calc'!$R$2:$R$2698=$B40)*INDEX('Retention Calc'!$B$2:$Q$2698,0,MATCH($B40+J$26,'Retention Calc'!$B$1:$Q$1,0)))/$C40),"")} | K40: {=IFERROR(IF($B40+K$26>2026,"",SUMPRODUCT(('Retention Calc'!$R$2:$R$2698=$B40)*INDEX('Retention Calc'!$B$2:$Q$2698,0,MATCH($B40+K$26,'Retention Calc'!$B$1:$Q$1,0)))/$C40),"")} | ... S40: {=IFERROR(IF($B40+S$26>2026,"",SUMPRODUCT(('Retention Calc'!$R$2:$R$2698=$B40)*INDEX('Retention Calc'!$B$2:$Q$2698,0,MATCH($B40+S$26,'Retention Calc'!$B$1:$Q$1,0)))/$C40),"")} | V40: ="Year "&13 -> Year 13 | W40: =IF(Q27="",NA(),Q27) -> 0.24332344 | X40: =IF(Q28="",NA(),Q28) -> 0.17073171 | Y40: =IF(Q29="",NA(),Q29) -> 0.1037037 | Z40: =IF(Q30="",NA(),Q30) -> #N/A | AA40: =IF(Q31="",NA(),Q31) -> #N/A | AB40: =IF(Q32="",NA(),Q32) -> #N/A | AC40: =IF(Q33="",NA(),Q33) -> #N/A | AD40: =IF(Q34="",NA(),Q34) -> #N/A | AE40: =IF(Q35="",NA(),Q35) -> #N/A | AF40: =IF(Q36="",NA(),Q36) -> #N/A | AG40: =IF(Q37="",NA(),Q37) -> #N/A | AH40: =IF(Q38="",NA(),Q38) -> #N/A | AI40: =IF(Q39="",NA(),Q39) -> #N/A | AJ40: =IF(Q40="",NA(),Q40) -> #N/A | AK40: =IF(Q41="",NA(),Q41) -> #N/A | AL40: =IF(Q42="",NA(),Q42) -> #N/A | AM40: =IF(Q43="",NA(),Q43) -> 0.19496855 | AN40: ="FY"&B40 -> FY2024
B41: =B40+1 -> 2025 | C41: =COUNTIF('Retention Calc'!$R$2:$R$2698,$B41) -> 161 | D41: {=IFERROR(IF($B41+D$26>2026,"",SUMPRODUCT(('Retention Calc'!$R$2:$R$2698=$B41)*INDEX('Retention Calc'!$B$2:$Q$2698,0,MATCH($B41+D$26,'Retention Calc'!$B$1:$Q$1,0)))/$C41),"")} -> 1 | E41: {=IFERROR(IF($B41+E$26>2026,"",SUMPRODUCT(('Retention Calc'!$R$2:$R$2698=$B41)*INDEX('Retention Calc'!$B$2:$Q$2698,0,MATCH($B41+E$26,'Retention Calc'!$B$1:$Q$1,0)))/$C41),"")} -> 0.19875776 | F41: {=IFERROR(IF($B41+F$26>2026,"",SUMPRODUCT(('Retention Calc'!$R$2:$R$2698=$B41)*INDEX('Retention Calc'!$B$2:$Q$2698,0,MATCH($B41+F$26,'Retention Calc'!$B$1:$Q$1,0)))/$C41),"")} | G41: {=IFERROR(IF($B41+G$26>2026,"",SUMPRODUCT(('Retention Calc'!$R$2:$R$2698=$B41)*INDEX('Retention Calc'!$B$2:$Q$2698,0,MATCH($B41+G$26,'Retention Calc'!$B$1:$Q$1,0)))/$C41),"")} | H41: {=IFERROR(IF($B41+H$26>2026,"",SUMPRODUCT(('Retention Calc'!$R$2:$R$2698=$B41)*INDEX('Retention Calc'!$B$2:$Q$2698,0,MATCH($B41+H$26,'Retention Calc'!$B$1:$Q$1,0)))/$C41),"")} | I41: {=IFERROR(IF($B41+I$26>2026,"",SUMPRODUCT(('Retention Calc'!$R$2:$R$2698=$B41)*INDEX('Retention Calc'!$B$2:$Q$2698,0,MATCH($B41+I$26,'Retention Calc'!$B$1:$Q$1,0)))/$C41),"")} | J41: {=IFERROR(IF($B41+J$26>2026,"",SUMPRODUCT(('Retention Calc'!$R$2:$R$2698=$B41)*INDEX('Retention Calc'!$B$2:$Q$2698,0,MATCH($B41+J$26,'Retention Calc'!$B$1:$Q$1,0)))/$C41),"")} | K41: {=IFERROR(IF($B41+K$26>2026,"",SUMPRODUCT(('Retention Calc'!$R$2:$R$2698=$B41)*INDEX('Retention Calc'!$B$2:$Q$2698,0,MATCH($B41+K$26,'Retention Calc'!$B$1:$Q$1,0)))/$C41),"")} | ... S41: {=IFERROR(IF($B41+S$26>2026,"",SUMPRODUCT(('Retention Calc'!$R$2:$R$2698=$B41)*INDEX('Retention Calc'!$B$2:$Q$2698,0,MATCH($B41+S$26,'Retention Calc'!$B$1:$Q$1,0)))/$C41),"")} | V41: ="Year "&14 -> Year 14 | W41: =IF(R27="",NA(),R27) -> 0.21958457 | X41: =IF(R28="",NA(),R28) -> 0.16463415 | Y41: =IF(R29="",NA(),R29) -> #N/A | Z41: =IF(R30="",NA(),R30) -> #N/A | AA41: =IF(R31="",NA(),R31) -> #N/A | AB41: =IF(R32="",NA(),R32) -> #N/A | AC41: =IF(R33="",NA(),R33) -> #N/A | AD41: =IF(R34="",NA(),R34) -> #N/A | AE41: =IF(R35="",NA(),R35) -> #N/A | AF41: =IF(R36="",NA(),R36) -> #N/A | AG41: =IF(R37="",NA(),R37) -> #N/A | AH41: =IF(R38="",NA(),R38) -> #N/A | AI41: =IF(R39="",NA(),R39) -> #N/A | AJ41: =IF(R40="",NA(),R40) -> #N/A | AK41: =IF(R41="",NA(),R41) -> #N/A | AL41: =IF(R42="",NA(),R42) -> #N/A | AM41: =IF(R43="",NA(),R43) -> 0.20159681 | AN41: ="FY"&B41 -> FY2025
